2021-06-23: SQL Database reported an error: (1406, "Data too long for column 'description' at row 1") 
 query: INSERT INTO account (id, username, description, followers_count, following_count, tweet_count, listed_count, verified, created_at) VALUES ("39973121", "meionorte", "O GMNC é o maior do Piauí. Através das Rádios MN FM, Boa FM, Cocais FM, da TV Jornal, Rede MN, Jornal MN e https://t.co/aPqnwYP6l1, levamos conteúdo regional pro Brasil", "21853", "103", "152678", "165", "1", "2009-05-14") ON DUPLICATE KEY UPDATE id="39973121", username="meionorte", description="O GMNC é o maior do Piauí. Através das Rádios MN FM, Boa FM, Cocais FM, da TV Jornal, Rede MN, Jornal MN e https://t.co/aPqnwYP6l1, levamos conteúdo regional pro Brasil", followers_count="21853", following_count="103", tweet_count="152678", listed_count="165", verified="1", created_at="2009-05-14";Traceback (most recent call last):
  File "C:\Users\gafel\Documents\GitHub\twittery\src\database\sql\sql.py", line 28, in query
    self.cursor.execute(query)
  File "C:\Users\gafel\AppData\Local\Programs\Python\Python39\lib\site-packages\pymysql\cursors.py", line 148, in execute
    result = self._query(query)
  File "C:\Users\gafel\AppData\Local\Programs\Python\Python39\lib\site-packages\pymysql\cursors.py", line 310, in _query
    conn.query(q)
  File "C:\Users\gafel\AppData\Local\Programs\Python\Python39\lib\site-packages\pymysql\connections.py", line 548, in query
    self._affected_rows = self._read_query_result(unbuffered=unbuffered)
  File "C:\Users\gafel\AppData\Local\Programs\Python\Python39\lib\site-packages\pymysql\connections.py", line 775, in _read_query_result
    result.read()
  File "C:\Users\gafel\AppData\Local\Programs\Python\Python39\lib\site-packages\pymysql\connections.py", line 1156, in read
    first_packet = self.connection._read_packet()
  File "C:\Users\gafel\AppData\Local\Programs\Python\Python39\lib\site-packages\pymysql\connections.py", line 725, in _read_packet
    packet.raise_for_error()
  File "C:\Users\gafel\AppData\Local\Programs\Python\Python39\lib\site-packages\pymysql\protocol.py", line 221, in raise_for_error
    err.raise_mysql_exception(self._data)
  File "C:\Users\gafel\AppData\Local\Programs\Python\Python39\lib\site-packages\pymysql\err.py", line 143, in raise_mysql_exception
    raise errorclass(errno, errval)
pymysql.err.DataError: (1406, "Data too long for column 'description' at row 1")
2021-06-23: SQL Database reported an error: (1406, "Data too long for column 'description' at row 1") 
 query: INSERT INTO account (id, username, description, followers_count, following_count, tweet_count, listed_count, verified, created_at) VALUES ("64643056", "RT_com", "Freedom over censorship, truth over narrative On air in 100+ countries. 10+ bn video views in 2020 Don’t want your news filtered - find us at https://t.co/jiqYHtdoFC", "2967905", "686", "390849", "20705", "1", "2009-08-11") ON DUPLICATE KEY UPDATE id="64643056", username="RT_com", description="Freedom over censorship, truth over narrative On air in 100+ countries. 10+ bn video views in 2020 Don’t want your news filtered - find us at https://t.co/jiqYHtdoFC", followers_count="2967905", following_count="686", tweet_count="390849", listed_count="20705", verified="1", created_at="2009-08-11";Traceback (most recent call last):
  File "C:\Users\gafel\Documents\GitHub\twittery\src\database\sql\sql.py", line 28, in query
    self.cursor.execute(query)
  File "C:\Users\gafel\AppData\Local\Programs\Python\Python39\lib\site-packages\pymysql\cursors.py", line 148, in execute
    result = self._query(query)
  File "C:\Users\gafel\AppData\Local\Programs\Python\Python39\lib\site-packages\pymysql\cursors.py", line 310, in _query
    conn.query(q)
  File "C:\Users\gafel\AppData\Local\Programs\Python\Python39\lib\site-packages\pymysql\connections.py", line 548, in query
    self._affected_rows = self._read_query_result(unbuffered=unbuffered)
  File "C:\Users\gafel\AppData\Local\Programs\Python\Python39\lib\site-packages\pymysql\connections.py", line 775, in _read_query_result
    result.read()
  File "C:\Users\gafel\AppData\Local\Programs\Python\Python39\lib\site-packages\pymysql\connections.py", line 1156, in read
    first_packet = self.connection._read_packet()
  File "C:\Users\gafel\AppData\Local\Programs\Python\Python39\lib\site-packages\pymysql\connections.py", line 725, in _read_packet
    packet.raise_for_error()
  File "C:\Users\gafel\AppData\Local\Programs\Python\Python39\lib\site-packages\pymysql\protocol.py", line 221, in raise_for_error
    err.raise_mysql_exception(self._data)
  File "C:\Users\gafel\AppData\Local\Programs\Python\Python39\lib\site-packages\pymysql\err.py", line 143, in raise_mysql_exception
    raise errorclass(errno, errval)
pymysql.err.DataError: (1406, "Data too long for column 'description' at row 1")
