2021-06-06: SQL Database reported an error: (1064, "You have an error in your SQL syntax; check the manual that corresponds to your MySQL server version for the right syntax to use near '2019 para cá, foram 70 ativos de infraestrutura transferidos para a iniciativa ' at line 1") 
Traceback (most recent call last):
  File "C:\Users\gafel\Documents\GitHub\twittery\src\db\sql\sql.py", line 23, in query
    self.cursor.execute(query)
  File "C:\Users\gafel\AppData\Local\Programs\Python\Python39\lib\site-packages\pymysql\cursors.py", line 148, in execute
    result = self._query(query)
  File "C:\Users\gafel\AppData\Local\Programs\Python\Python39\lib\site-packages\pymysql\cursors.py", line 310, in _query
    conn.query(q)
  File "C:\Users\gafel\AppData\Local\Programs\Python\Python39\lib\site-packages\pymysql\connections.py", line 548, in query
    self._affected_rows = self._read_query_result(unbuffered=unbuffered)
  File "C:\Users\gafel\AppData\Local\Programs\Python\Python39\lib\site-packages\pymysql\connections.py", line 775, in _read_query_result
    result.read()
  File "C:\Users\gafel\AppData\Local\Programs\Python\Python39\lib\site-packages\pymysql\connections.py", line 1156, in read
    first_packet = self.connection._read_packet()
  File "C:\Users\gafel\AppData\Local\Programs\Python\Python39\lib\site-packages\pymysql\connections.py", line 725, in _read_packet
    packet.raise_for_error()
  File "C:\Users\gafel\AppData\Local\Programs\Python\Python39\lib\site-packages\pymysql\protocol.py", line 221, in raise_for_error
    err.raise_mysql_exception(self._data)
  File "C:\Users\gafel\AppData\Local\Programs\Python\Python39\lib\site-packages\pymysql\err.py", line 143, in raise_mysql_exception
    raise errorclass(errno, errval)
pymysql.err.ProgrammingError: (1064, "You have an error in your SQL syntax; check the manual that corresponds to your MySQL server version for the right syntax to use near '2019 para cá, foram 70 ativos de infraestrutura transferidos para a iniciativa ' at line 1")
2021-06-06: SQL Database reported an error: (1064, "You have an error in your SQL syntax; check the manual that corresponds to your MySQL server version for the right syntax to use near '2019 para cá, foram 70 ativos de infraestrutura transferidos para a iniciativa ' at line 1") 
Traceback (most recent call last):
  File "C:\Users\gafel\Documents\GitHub\twittery\src\db\sql\sql.py", line 23, in query
    self.cursor.execute(query)
  File "C:\Users\gafel\AppData\Local\Programs\Python\Python39\lib\site-packages\pymysql\cursors.py", line 148, in execute
    result = self._query(query)
  File "C:\Users\gafel\AppData\Local\Programs\Python\Python39\lib\site-packages\pymysql\cursors.py", line 310, in _query
    conn.query(q)
  File "C:\Users\gafel\AppData\Local\Programs\Python\Python39\lib\site-packages\pymysql\connections.py", line 548, in query
    self._affected_rows = self._read_query_result(unbuffered=unbuffered)
  File "C:\Users\gafel\AppData\Local\Programs\Python\Python39\lib\site-packages\pymysql\connections.py", line 775, in _read_query_result
    result.read()
  File "C:\Users\gafel\AppData\Local\Programs\Python\Python39\lib\site-packages\pymysql\connections.py", line 1156, in read
    first_packet = self.connection._read_packet()
  File "C:\Users\gafel\AppData\Local\Programs\Python\Python39\lib\site-packages\pymysql\connections.py", line 725, in _read_packet
    packet.raise_for_error()
  File "C:\Users\gafel\AppData\Local\Programs\Python\Python39\lib\site-packages\pymysql\protocol.py", line 221, in raise_for_error
    err.raise_mysql_exception(self._data)
  File "C:\Users\gafel\AppData\Local\Programs\Python\Python39\lib\site-packages\pymysql\err.py", line 143, in raise_mysql_exception
    raise errorclass(errno, errval)
pymysql.err.ProgrammingError: (1064, "You have an error in your SQL syntax; check the manual that corresponds to your MySQL server version for the right syntax to use near '2019 para cá, foram 70 ativos de infraestrutura transferidos para a iniciativa ' at line 1")
2021-06-17: SQL Database reported an error: (2003, "Can't connect to MySQL server on 'localhost' ([WinError 10061] Nenhuma conexão pôde ser feita porque a máquina de destino as recusou ativamente)") 
Traceback (most recent call last):
  File "C:\Users\gafel\AppData\Local\Programs\Python\Python39\lib\site-packages\pymysql\connections.py", line 613, in connect
    sock = socket.create_connection(
  File "C:\Users\gafel\AppData\Local\Programs\Python\Python39\lib\socket.py", line 843, in create_connection
    raise err
  File "C:\Users\gafel\AppData\Local\Programs\Python\Python39\lib\socket.py", line 831, in create_connection
    sock.connect(sa)
ConnectionRefusedError: [WinError 10061] Nenhuma conexão pôde ser feita porque a máquina de destino as recusou ativamente

During handling of the above exception, another exception occurred:

Traceback (most recent call last):
  File "C:\Users\gafel\Documents\GitHub\twittery\src\database\sql\sql.py", line 12, in __init__
    self.db = pymysql.connect(host=host, port=port, user=user, passwd=password, db=db, charset='utf8')
  File "C:\Users\gafel\AppData\Local\Programs\Python\Python39\lib\site-packages\pymysql\connections.py", line 353, in __init__
    self.connect()
  File "C:\Users\gafel\AppData\Local\Programs\Python\Python39\lib\site-packages\pymysql\connections.py", line 664, in connect
    raise exc
pymysql.err.OperationalError: (2003, "Can't connect to MySQL server on 'localhost' ([WinError 10061] Nenhuma conexão pôde ser feita porque a máquina de destino as recusou ativamente)")
2021-06-17: SQL Database reported an error: (2003, "Can't connect to MySQL server on 'localhost' ([WinError 10061] Nenhuma conexão pôde ser feita porque a máquina de destino as recusou ativamente)") 
Traceback (most recent call last):
  File "C:\Users\gafel\AppData\Local\Programs\Python\Python39\lib\site-packages\pymysql\connections.py", line 613, in connect
    sock = socket.create_connection(
  File "C:\Users\gafel\AppData\Local\Programs\Python\Python39\lib\socket.py", line 843, in create_connection
    raise err
  File "C:\Users\gafel\AppData\Local\Programs\Python\Python39\lib\socket.py", line 831, in create_connection
    sock.connect(sa)
ConnectionRefusedError: [WinError 10061] Nenhuma conexão pôde ser feita porque a máquina de destino as recusou ativamente

During handling of the above exception, another exception occurred:

Traceback (most recent call last):
  File "C:\Users\gafel\Documents\GitHub\twittery\src\database\sql\sql.py", line 12, in __init__
    self.db = pymysql.connect(host=host, port=port, user=user, passwd=password, db=db, charset='utf8')
  File "C:\Users\gafel\AppData\Local\Programs\Python\Python39\lib\site-packages\pymysql\connections.py", line 353, in __init__
    self.connect()
  File "C:\Users\gafel\AppData\Local\Programs\Python\Python39\lib\site-packages\pymysql\connections.py", line 664, in connect
    raise exc
pymysql.err.OperationalError: (2003, "Can't connect to MySQL server on 'localhost' ([WinError 10061] Nenhuma conexão pôde ser feita porque a máquina de destino as recusou ativamente)")
2021-06-17: SQL Database reported an error: (2003, "Can't connect to MySQL server on 'localhost' ([WinError 10061] Nenhuma conexão pôde ser feita porque a máquina de destino as recusou ativamente)") 
Traceback (most recent call last):
  File "C:\Users\gafel\AppData\Local\Programs\Python\Python39\lib\site-packages\pymysql\connections.py", line 613, in connect
    sock = socket.create_connection(
  File "C:\Users\gafel\AppData\Local\Programs\Python\Python39\lib\socket.py", line 843, in create_connection
    raise err
  File "C:\Users\gafel\AppData\Local\Programs\Python\Python39\lib\socket.py", line 831, in create_connection
    sock.connect(sa)
ConnectionRefusedError: [WinError 10061] Nenhuma conexão pôde ser feita porque a máquina de destino as recusou ativamente

During handling of the above exception, another exception occurred:

Traceback (most recent call last):
  File "C:\Users\gafel\Documents\GitHub\twittery\src\database\sql\sql.py", line 12, in __init__
    self.db = pymysql.connect(host=host, port=port, user=user, passwd=password, db=db, charset='utf8')
  File "C:\Users\gafel\AppData\Local\Programs\Python\Python39\lib\site-packages\pymysql\connections.py", line 353, in __init__
    self.connect()
  File "C:\Users\gafel\AppData\Local\Programs\Python\Python39\lib\site-packages\pymysql\connections.py", line 664, in connect
    raise exc
pymysql.err.OperationalError: (2003, "Can't connect to MySQL server on 'localhost' ([WinError 10061] Nenhuma conexão pôde ser feita porque a máquina de destino as recusou ativamente)")
2021-06-17: SQL Database reported an error: (2003, "Can't connect to MySQL server on 'localhost' ([WinError 10061] Nenhuma conexão pôde ser feita porque a máquina de destino as recusou ativamente)") 
Traceback (most recent call last):
  File "C:\Users\gafel\AppData\Local\Programs\Python\Python39\lib\site-packages\pymysql\connections.py", line 613, in connect
    sock = socket.create_connection(
  File "C:\Users\gafel\AppData\Local\Programs\Python\Python39\lib\socket.py", line 843, in create_connection
    raise err
  File "C:\Users\gafel\AppData\Local\Programs\Python\Python39\lib\socket.py", line 831, in create_connection
    sock.connect(sa)
ConnectionRefusedError: [WinError 10061] Nenhuma conexão pôde ser feita porque a máquina de destino as recusou ativamente

During handling of the above exception, another exception occurred:

Traceback (most recent call last):
  File "C:\Users\gafel\Documents\GitHub\twittery\src\database\sql\sql.py", line 12, in __init__
    self.db = pymysql.connect(host=host, port=port, user=user, passwd=password, db=db, charset='utf8')
  File "C:\Users\gafel\AppData\Local\Programs\Python\Python39\lib\site-packages\pymysql\connections.py", line 353, in __init__
    self.connect()
  File "C:\Users\gafel\AppData\Local\Programs\Python\Python39\lib\site-packages\pymysql\connections.py", line 664, in connect
    raise exc
pymysql.err.OperationalError: (2003, "Can't connect to MySQL server on 'localhost' ([WinError 10061] Nenhuma conexão pôde ser feita porque a máquina de destino as recusou ativamente)")
2021-06-17: SQL Database reported an error: (2003, "Can't connect to MySQL server on 'localhost' ([WinError 10061] Nenhuma conexão pôde ser feita porque a máquina de destino as recusou ativamente)") 
Traceback (most recent call last):
  File "C:\Users\gafel\AppData\Local\Programs\Python\Python39\lib\site-packages\pymysql\connections.py", line 613, in connect
    sock = socket.create_connection(
  File "C:\Users\gafel\AppData\Local\Programs\Python\Python39\lib\socket.py", line 843, in create_connection
    raise err
  File "C:\Users\gafel\AppData\Local\Programs\Python\Python39\lib\socket.py", line 831, in create_connection
    sock.connect(sa)
ConnectionRefusedError: [WinError 10061] Nenhuma conexão pôde ser feita porque a máquina de destino as recusou ativamente

During handling of the above exception, another exception occurred:

Traceback (most recent call last):
  File "C:\Users\gafel\Documents\GitHub\twittery\src\database\sql\sql.py", line 12, in __init__
    self.db = pymysql.connect(host=host, port=port, user=user, passwd=password, db=db, charset='utf8')
  File "C:\Users\gafel\AppData\Local\Programs\Python\Python39\lib\site-packages\pymysql\connections.py", line 353, in __init__
    self.connect()
  File "C:\Users\gafel\AppData\Local\Programs\Python\Python39\lib\site-packages\pymysql\connections.py", line 664, in connect
    raise exc
pymysql.err.OperationalError: (2003, "Can't connect to MySQL server on 'localhost' ([WinError 10061] Nenhuma conexão pôde ser feita porque a máquina de destino as recusou ativamente)")
2021-06-17: SQL Database reported an error: (2003, "Can't connect to MySQL server on 'localhost' ([WinError 10061] Nenhuma conexão pôde ser feita porque a máquina de destino as recusou ativamente)") 
Traceback (most recent call last):
  File "C:\Users\gafel\AppData\Local\Programs\Python\Python39\lib\site-packages\pymysql\connections.py", line 613, in connect
    sock = socket.create_connection(
  File "C:\Users\gafel\AppData\Local\Programs\Python\Python39\lib\socket.py", line 843, in create_connection
    raise err
  File "C:\Users\gafel\AppData\Local\Programs\Python\Python39\lib\socket.py", line 831, in create_connection
    sock.connect(sa)
ConnectionRefusedError: [WinError 10061] Nenhuma conexão pôde ser feita porque a máquina de destino as recusou ativamente

During handling of the above exception, another exception occurred:

Traceback (most recent call last):
  File "C:\Users\gafel\Documents\GitHub\twittery\src\database\sql\sql.py", line 12, in __init__
    self.db = pymysql.connect(host=host, port=port, user=user, passwd=password, db=db, charset='utf8')
  File "C:\Users\gafel\AppData\Local\Programs\Python\Python39\lib\site-packages\pymysql\connections.py", line 353, in __init__
    self.connect()
  File "C:\Users\gafel\AppData\Local\Programs\Python\Python39\lib\site-packages\pymysql\connections.py", line 664, in connect
    raise exc
pymysql.err.OperationalError: (2003, "Can't connect to MySQL server on 'localhost' ([WinError 10061] Nenhuma conexão pôde ser feita porque a máquina de destino as recusou ativamente)")
2021-06-17: SQL Database reported an error: (2003, "Can't connect to MySQL server on 'localhost' ([WinError 10061] Nenhuma conexão pôde ser feita porque a máquina de destino as recusou ativamente)") 
Traceback (most recent call last):
  File "C:\Users\gafel\AppData\Local\Programs\Python\Python39\lib\site-packages\pymysql\connections.py", line 613, in connect
    sock = socket.create_connection(
  File "C:\Users\gafel\AppData\Local\Programs\Python\Python39\lib\socket.py", line 843, in create_connection
    raise err
  File "C:\Users\gafel\AppData\Local\Programs\Python\Python39\lib\socket.py", line 831, in create_connection
    sock.connect(sa)
ConnectionRefusedError: [WinError 10061] Nenhuma conexão pôde ser feita porque a máquina de destino as recusou ativamente

During handling of the above exception, another exception occurred:

Traceback (most recent call last):
  File "C:\Users\gafel\Documents\GitHub\twittery\src\database\sql\sql.py", line 12, in __init__
    self.db = pymysql.connect(host=host, port=port, user=user, passwd=password, db=db, charset='utf8')
  File "C:\Users\gafel\AppData\Local\Programs\Python\Python39\lib\site-packages\pymysql\connections.py", line 353, in __init__
    self.connect()
  File "C:\Users\gafel\AppData\Local\Programs\Python\Python39\lib\site-packages\pymysql\connections.py", line 664, in connect
    raise exc
pymysql.err.OperationalError: (2003, "Can't connect to MySQL server on 'localhost' ([WinError 10061] Nenhuma conexão pôde ser feita porque a máquina de destino as recusou ativamente)")
2021-06-17: SQL Database reported an error: (2003, "Can't connect to MySQL server on 'localhost' ([WinError 10061] Nenhuma conexão pôde ser feita porque a máquina de destino as recusou ativamente)") 
Traceback (most recent call last):
  File "C:\Users\gafel\AppData\Local\Programs\Python\Python39\lib\site-packages\pymysql\connections.py", line 613, in connect
    sock = socket.create_connection(
  File "C:\Users\gafel\AppData\Local\Programs\Python\Python39\lib\socket.py", line 843, in create_connection
    raise err
  File "C:\Users\gafel\AppData\Local\Programs\Python\Python39\lib\socket.py", line 831, in create_connection
    sock.connect(sa)
ConnectionRefusedError: [WinError 10061] Nenhuma conexão pôde ser feita porque a máquina de destino as recusou ativamente

During handling of the above exception, another exception occurred:

Traceback (most recent call last):
  File "C:\Users\gafel\Documents\GitHub\twittery\src\database\sql\sql.py", line 12, in __init__
    self.db = pymysql.connect(host=host, port=port, user=user, passwd=password, db=db, charset='utf8')
  File "C:\Users\gafel\AppData\Local\Programs\Python\Python39\lib\site-packages\pymysql\connections.py", line 353, in __init__
    self.connect()
  File "C:\Users\gafel\AppData\Local\Programs\Python\Python39\lib\site-packages\pymysql\connections.py", line 664, in connect
    raise exc
pymysql.err.OperationalError: (2003, "Can't connect to MySQL server on 'localhost' ([WinError 10061] Nenhuma conexão pôde ser feita porque a máquina de destino as recusou ativamente)")
2021-06-17: SQL Database reported an error: (2003, "Can't connect to MySQL server on 'localhost' ([WinError 10061] Nenhuma conexão pôde ser feita porque a máquina de destino as recusou ativamente)") 
Traceback (most recent call last):
  File "C:\Users\gafel\AppData\Local\Programs\Python\Python39\lib\site-packages\pymysql\connections.py", line 613, in connect
    sock = socket.create_connection(
  File "C:\Users\gafel\AppData\Local\Programs\Python\Python39\lib\socket.py", line 843, in create_connection
    raise err
  File "C:\Users\gafel\AppData\Local\Programs\Python\Python39\lib\socket.py", line 831, in create_connection
    sock.connect(sa)
ConnectionRefusedError: [WinError 10061] Nenhuma conexão pôde ser feita porque a máquina de destino as recusou ativamente

During handling of the above exception, another exception occurred:

Traceback (most recent call last):
  File "C:\Users\gafel\Documents\GitHub\twittery\src\database\sql\sql.py", line 12, in __init__
    self.db = pymysql.connect(host=host, port=port, user=user, passwd=password, db=db, charset='utf8')
  File "C:\Users\gafel\AppData\Local\Programs\Python\Python39\lib\site-packages\pymysql\connections.py", line 353, in __init__
    self.connect()
  File "C:\Users\gafel\AppData\Local\Programs\Python\Python39\lib\site-packages\pymysql\connections.py", line 664, in connect
    raise exc
pymysql.err.OperationalError: (2003, "Can't connect to MySQL server on 'localhost' ([WinError 10061] Nenhuma conexão pôde ser feita porque a máquina de destino as recusou ativamente)")
2021-06-17: SQL Database reported an error: (2003, "Can't connect to MySQL server on 'localhost' ([WinError 10061] Nenhuma conexão pôde ser feita porque a máquina de destino as recusou ativamente)") 
Traceback (most recent call last):
  File "C:\Users\gafel\AppData\Local\Programs\Python\Python39\lib\site-packages\pymysql\connections.py", line 613, in connect
    sock = socket.create_connection(
  File "C:\Users\gafel\AppData\Local\Programs\Python\Python39\lib\socket.py", line 843, in create_connection
    raise err
  File "C:\Users\gafel\AppData\Local\Programs\Python\Python39\lib\socket.py", line 831, in create_connection
    sock.connect(sa)
ConnectionRefusedError: [WinError 10061] Nenhuma conexão pôde ser feita porque a máquina de destino as recusou ativamente

During handling of the above exception, another exception occurred:

Traceback (most recent call last):
  File "C:\Users\gafel\Documents\GitHub\twittery\src\database\sql\sql.py", line 12, in __init__
    self.db = pymysql.connect(host=host, port=port, user=user, passwd=password, db=db, charset='utf8')
  File "C:\Users\gafel\AppData\Local\Programs\Python\Python39\lib\site-packages\pymysql\connections.py", line 353, in __init__
    self.connect()
  File "C:\Users\gafel\AppData\Local\Programs\Python\Python39\lib\site-packages\pymysql\connections.py", line 664, in connect
    raise exc
pymysql.err.OperationalError: (2003, "Can't connect to MySQL server on 'localhost' ([WinError 10061] Nenhuma conexão pôde ser feita porque a máquina de destino as recusou ativamente)")
2021-06-17: SQL Database reported an error: (2003, "Can't connect to MySQL server on 'localhost' ([WinError 10061] Nenhuma conexão pôde ser feita porque a máquina de destino as recusou ativamente)") 
Traceback (most recent call last):
  File "C:\Users\gafel\AppData\Local\Programs\Python\Python39\lib\site-packages\pymysql\connections.py", line 613, in connect
    sock = socket.create_connection(
  File "C:\Users\gafel\AppData\Local\Programs\Python\Python39\lib\socket.py", line 843, in create_connection
    raise err
  File "C:\Users\gafel\AppData\Local\Programs\Python\Python39\lib\socket.py", line 831, in create_connection
    sock.connect(sa)
ConnectionRefusedError: [WinError 10061] Nenhuma conexão pôde ser feita porque a máquina de destino as recusou ativamente

During handling of the above exception, another exception occurred:

Traceback (most recent call last):
  File "C:\Users\gafel\Documents\GitHub\twittery\src\database\sql\sql.py", line 12, in __init__
    self.db = pymysql.connect(host=host, port=port, user=user, passwd=password, db=db, charset='utf8')
  File "C:\Users\gafel\AppData\Local\Programs\Python\Python39\lib\site-packages\pymysql\connections.py", line 353, in __init__
    self.connect()
  File "C:\Users\gafel\AppData\Local\Programs\Python\Python39\lib\site-packages\pymysql\connections.py", line 664, in connect
    raise exc
pymysql.err.OperationalError: (2003, "Can't connect to MySQL server on 'localhost' ([WinError 10061] Nenhuma conexão pôde ser feita porque a máquina de destino as recusou ativamente)")
2021-06-17: SQL Database reported an error: (2003, "Can't connect to MySQL server on 'localhost' ([WinError 10061] Nenhuma conexão pôde ser feita porque a máquina de destino as recusou ativamente)") 
Traceback (most recent call last):
  File "C:\Users\gafel\AppData\Local\Programs\Python\Python39\lib\site-packages\pymysql\connections.py", line 613, in connect
    sock = socket.create_connection(
  File "C:\Users\gafel\AppData\Local\Programs\Python\Python39\lib\socket.py", line 843, in create_connection
    raise err
  File "C:\Users\gafel\AppData\Local\Programs\Python\Python39\lib\socket.py", line 831, in create_connection
    sock.connect(sa)
ConnectionRefusedError: [WinError 10061] Nenhuma conexão pôde ser feita porque a máquina de destino as recusou ativamente

During handling of the above exception, another exception occurred:

Traceback (most recent call last):
  File "C:\Users\gafel\Documents\GitHub\twittery\src\database\sql\sql.py", line 12, in __init__
    self.db = pymysql.connect(host=host, port=port, user=user, passwd=password, db=db, charset='utf8')
  File "C:\Users\gafel\AppData\Local\Programs\Python\Python39\lib\site-packages\pymysql\connections.py", line 353, in __init__
    self.connect()
  File "C:\Users\gafel\AppData\Local\Programs\Python\Python39\lib\site-packages\pymysql\connections.py", line 664, in connect
    raise exc
pymysql.err.OperationalError: (2003, "Can't connect to MySQL server on 'localhost' ([WinError 10061] Nenhuma conexão pôde ser feita porque a máquina de destino as recusou ativamente)")
2021-06-17: SQL Database reported an error: (2003, "Can't connect to MySQL server on 'localhost' ([WinError 10061] Nenhuma conexão pôde ser feita porque a máquina de destino as recusou ativamente)") 
Traceback (most recent call last):
  File "C:\Users\gafel\AppData\Local\Programs\Python\Python39\lib\site-packages\pymysql\connections.py", line 613, in connect
    sock = socket.create_connection(
  File "C:\Users\gafel\AppData\Local\Programs\Python\Python39\lib\socket.py", line 843, in create_connection
    raise err
  File "C:\Users\gafel\AppData\Local\Programs\Python\Python39\lib\socket.py", line 831, in create_connection
    sock.connect(sa)
ConnectionRefusedError: [WinError 10061] Nenhuma conexão pôde ser feita porque a máquina de destino as recusou ativamente

During handling of the above exception, another exception occurred:

Traceback (most recent call last):
  File "C:\Users\gafel\Documents\GitHub\twittery\src\database\sql\sql.py", line 12, in __init__
    self.db = pymysql.connect(host=host, port=port, user=user, passwd=password, db=db, charset='utf8')
  File "C:\Users\gafel\AppData\Local\Programs\Python\Python39\lib\site-packages\pymysql\connections.py", line 353, in __init__
    self.connect()
  File "C:\Users\gafel\AppData\Local\Programs\Python\Python39\lib\site-packages\pymysql\connections.py", line 664, in connect
    raise exc
pymysql.err.OperationalError: (2003, "Can't connect to MySQL server on 'localhost' ([WinError 10061] Nenhuma conexão pôde ser feita porque a máquina de destino as recusou ativamente)")
2021-06-17: SQL Database reported an error: (2003, "Can't connect to MySQL server on 'localhost' ([WinError 10061] Nenhuma conexão pôde ser feita porque a máquina de destino as recusou ativamente)") 
Traceback (most recent call last):
  File "C:\Users\gafel\AppData\Local\Programs\Python\Python39\lib\site-packages\pymysql\connections.py", line 613, in connect
    sock = socket.create_connection(
  File "C:\Users\gafel\AppData\Local\Programs\Python\Python39\lib\socket.py", line 843, in create_connection
    raise err
  File "C:\Users\gafel\AppData\Local\Programs\Python\Python39\lib\socket.py", line 831, in create_connection
    sock.connect(sa)
ConnectionRefusedError: [WinError 10061] Nenhuma conexão pôde ser feita porque a máquina de destino as recusou ativamente

During handling of the above exception, another exception occurred:

Traceback (most recent call last):
  File "C:\Users\gafel\Documents\GitHub\twittery\src\database\sql\sql.py", line 12, in __init__
    self.db = pymysql.connect(host=host, port=port, user=user, passwd=password, db=db, charset='utf8')
  File "C:\Users\gafel\AppData\Local\Programs\Python\Python39\lib\site-packages\pymysql\connections.py", line 353, in __init__
    self.connect()
  File "C:\Users\gafel\AppData\Local\Programs\Python\Python39\lib\site-packages\pymysql\connections.py", line 664, in connect
    raise exc
pymysql.err.OperationalError: (2003, "Can't connect to MySQL server on 'localhost' ([WinError 10061] Nenhuma conexão pôde ser feita porque a máquina de destino as recusou ativamente)")
2021-06-17: SQL Database reported an error: (2003, "Can't connect to MySQL server on 'localhost' ([WinError 10061] Nenhuma conexão pôde ser feita porque a máquina de destino as recusou ativamente)") 
Traceback (most recent call last):
  File "C:\Users\gafel\AppData\Local\Programs\Python\Python39\lib\site-packages\pymysql\connections.py", line 613, in connect
    sock = socket.create_connection(
  File "C:\Users\gafel\AppData\Local\Programs\Python\Python39\lib\socket.py", line 843, in create_connection
    raise err
  File "C:\Users\gafel\AppData\Local\Programs\Python\Python39\lib\socket.py", line 831, in create_connection
    sock.connect(sa)
ConnectionRefusedError: [WinError 10061] Nenhuma conexão pôde ser feita porque a máquina de destino as recusou ativamente

During handling of the above exception, another exception occurred:

Traceback (most recent call last):
  File "C:\Users\gafel\Documents\GitHub\twittery\src\database\sql\sql.py", line 12, in __init__
    self.db = pymysql.connect(host=host, port=port, user=user, passwd=password, db=db, charset='utf8')
  File "C:\Users\gafel\AppData\Local\Programs\Python\Python39\lib\site-packages\pymysql\connections.py", line 353, in __init__
    self.connect()
  File "C:\Users\gafel\AppData\Local\Programs\Python\Python39\lib\site-packages\pymysql\connections.py", line 664, in connect
    raise exc
pymysql.err.OperationalError: (2003, "Can't connect to MySQL server on 'localhost' ([WinError 10061] Nenhuma conexão pôde ser feita porque a máquina de destino as recusou ativamente)")
2021-06-17: SQL Database reported an error: (2003, "Can't connect to MySQL server on 'localhost' ([WinError 10061] Nenhuma conexão pôde ser feita porque a máquina de destino as recusou ativamente)") 
Traceback (most recent call last):
  File "C:\Users\gafel\AppData\Local\Programs\Python\Python39\lib\site-packages\pymysql\connections.py", line 613, in connect
    sock = socket.create_connection(
  File "C:\Users\gafel\AppData\Local\Programs\Python\Python39\lib\socket.py", line 843, in create_connection
    raise err
  File "C:\Users\gafel\AppData\Local\Programs\Python\Python39\lib\socket.py", line 831, in create_connection
    sock.connect(sa)
ConnectionRefusedError: [WinError 10061] Nenhuma conexão pôde ser feita porque a máquina de destino as recusou ativamente

During handling of the above exception, another exception occurred:

Traceback (most recent call last):
  File "C:\Users\gafel\Documents\GitHub\twittery\src\database\sql\sql.py", line 12, in __init__
    self.db = pymysql.connect(host=host, port=port, user=user, passwd=password, db=db, charset='utf8')
  File "C:\Users\gafel\AppData\Local\Programs\Python\Python39\lib\site-packages\pymysql\connections.py", line 353, in __init__
    self.connect()
  File "C:\Users\gafel\AppData\Local\Programs\Python\Python39\lib\site-packages\pymysql\connections.py", line 664, in connect
    raise exc
pymysql.err.OperationalError: (2003, "Can't connect to MySQL server on 'localhost' ([WinError 10061] Nenhuma conexão pôde ser feita porque a máquina de destino as recusou ativamente)")
2021-06-17: SQL Database reported an error: (2003, "Can't connect to MySQL server on 'localhost' ([WinError 10061] Nenhuma conexão pôde ser feita porque a máquina de destino as recusou ativamente)") 
Traceback (most recent call last):
  File "C:\Users\gafel\AppData\Local\Programs\Python\Python39\lib\site-packages\pymysql\connections.py", line 613, in connect
    sock = socket.create_connection(
  File "C:\Users\gafel\AppData\Local\Programs\Python\Python39\lib\socket.py", line 843, in create_connection
    raise err
  File "C:\Users\gafel\AppData\Local\Programs\Python\Python39\lib\socket.py", line 831, in create_connection
    sock.connect(sa)
ConnectionRefusedError: [WinError 10061] Nenhuma conexão pôde ser feita porque a máquina de destino as recusou ativamente

During handling of the above exception, another exception occurred:

Traceback (most recent call last):
  File "C:\Users\gafel\Documents\GitHub\twittery\src\database\sql\sql.py", line 12, in __init__
    self.db = pymysql.connect(host=host, port=port, user=user, passwd=password, db=db, charset='utf8')
  File "C:\Users\gafel\AppData\Local\Programs\Python\Python39\lib\site-packages\pymysql\connections.py", line 353, in __init__
    self.connect()
  File "C:\Users\gafel\AppData\Local\Programs\Python\Python39\lib\site-packages\pymysql\connections.py", line 664, in connect
    raise exc
pymysql.err.OperationalError: (2003, "Can't connect to MySQL server on 'localhost' ([WinError 10061] Nenhuma conexão pôde ser feita porque a máquina de destino as recusou ativamente)")
2021-06-17: SQL Database reported an error: (2003, "Can't connect to MySQL server on 'localhost' ([WinError 10061] Nenhuma conexão pôde ser feita porque a máquina de destino as recusou ativamente)") 
Traceback (most recent call last):
  File "C:\Users\gafel\AppData\Local\Programs\Python\Python39\lib\site-packages\pymysql\connections.py", line 613, in connect
    sock = socket.create_connection(
  File "C:\Users\gafel\AppData\Local\Programs\Python\Python39\lib\socket.py", line 843, in create_connection
    raise err
  File "C:\Users\gafel\AppData\Local\Programs\Python\Python39\lib\socket.py", line 831, in create_connection
    sock.connect(sa)
ConnectionRefusedError: [WinError 10061] Nenhuma conexão pôde ser feita porque a máquina de destino as recusou ativamente

During handling of the above exception, another exception occurred:

Traceback (most recent call last):
  File "C:\Users\gafel\Documents\GitHub\twittery\src\database\sql\sql.py", line 12, in __init__
    self.db = pymysql.connect(host=host, port=port, user=user, passwd=password, db=db, charset='utf8')
  File "C:\Users\gafel\AppData\Local\Programs\Python\Python39\lib\site-packages\pymysql\connections.py", line 353, in __init__
    self.connect()
  File "C:\Users\gafel\AppData\Local\Programs\Python\Python39\lib\site-packages\pymysql\connections.py", line 664, in connect
    raise exc
pymysql.err.OperationalError: (2003, "Can't connect to MySQL server on 'localhost' ([WinError 10061] Nenhuma conexão pôde ser feita porque a máquina de destino as recusou ativamente)")
2021-06-17: SQL Database reported an error: (2003, "Can't connect to MySQL server on 'localhost' ([WinError 10061] Nenhuma conexão pôde ser feita porque a máquina de destino as recusou ativamente)") 
Traceback (most recent call last):
  File "C:\Users\gafel\AppData\Local\Programs\Python\Python39\lib\site-packages\pymysql\connections.py", line 613, in connect
    sock = socket.create_connection(
  File "C:\Users\gafel\AppData\Local\Programs\Python\Python39\lib\socket.py", line 843, in create_connection
    raise err
  File "C:\Users\gafel\AppData\Local\Programs\Python\Python39\lib\socket.py", line 831, in create_connection
    sock.connect(sa)
ConnectionRefusedError: [WinError 10061] Nenhuma conexão pôde ser feita porque a máquina de destino as recusou ativamente

During handling of the above exception, another exception occurred:

Traceback (most recent call last):
  File "C:\Users\gafel\Documents\GitHub\twittery\src\database\sql\sql.py", line 12, in __init__
    self.db = pymysql.connect(host=host, port=port, user=user, passwd=password, db=db, charset='utf8')
  File "C:\Users\gafel\AppData\Local\Programs\Python\Python39\lib\site-packages\pymysql\connections.py", line 353, in __init__
    self.connect()
  File "C:\Users\gafel\AppData\Local\Programs\Python\Python39\lib\site-packages\pymysql\connections.py", line 664, in connect
    raise exc
pymysql.err.OperationalError: (2003, "Can't connect to MySQL server on 'localhost' ([WinError 10061] Nenhuma conexão pôde ser feita porque a máquina de destino as recusou ativamente)")
2021-06-17: SQL Database reported an error: (2003, "Can't connect to MySQL server on 'localhost' ([WinError 10061] Nenhuma conexão pôde ser feita porque a máquina de destino as recusou ativamente)") 
Traceback (most recent call last):
  File "C:\Users\gafel\AppData\Local\Programs\Python\Python39\lib\site-packages\pymysql\connections.py", line 613, in connect
    sock = socket.create_connection(
  File "C:\Users\gafel\AppData\Local\Programs\Python\Python39\lib\socket.py", line 843, in create_connection
    raise err
  File "C:\Users\gafel\AppData\Local\Programs\Python\Python39\lib\socket.py", line 831, in create_connection
    sock.connect(sa)
ConnectionRefusedError: [WinError 10061] Nenhuma conexão pôde ser feita porque a máquina de destino as recusou ativamente

During handling of the above exception, another exception occurred:

Traceback (most recent call last):
  File "C:\Users\gafel\Documents\GitHub\twittery\src\database\sql\sql.py", line 12, in __init__
    self.db = pymysql.connect(host=host, port=port, user=user, passwd=password, db=db, charset='utf8')
  File "C:\Users\gafel\AppData\Local\Programs\Python\Python39\lib\site-packages\pymysql\connections.py", line 353, in __init__
    self.connect()
  File "C:\Users\gafel\AppData\Local\Programs\Python\Python39\lib\site-packages\pymysql\connections.py", line 664, in connect
    raise exc
pymysql.err.OperationalError: (2003, "Can't connect to MySQL server on 'localhost' ([WinError 10061] Nenhuma conexão pôde ser feita porque a máquina de destino as recusou ativamente)")
2021-06-17: SQL Database reported an error: (2003, "Can't connect to MySQL server on 'localhost' ([WinError 10061] Nenhuma conexão pôde ser feita porque a máquina de destino as recusou ativamente)") 
Traceback (most recent call last):
  File "C:\Users\gafel\AppData\Local\Programs\Python\Python39\lib\site-packages\pymysql\connections.py", line 613, in connect
    sock = socket.create_connection(
  File "C:\Users\gafel\AppData\Local\Programs\Python\Python39\lib\socket.py", line 843, in create_connection
    raise err
  File "C:\Users\gafel\AppData\Local\Programs\Python\Python39\lib\socket.py", line 831, in create_connection
    sock.connect(sa)
ConnectionRefusedError: [WinError 10061] Nenhuma conexão pôde ser feita porque a máquina de destino as recusou ativamente

During handling of the above exception, another exception occurred:

Traceback (most recent call last):
  File "C:\Users\gafel\Documents\GitHub\twittery\src\database\sql\sql.py", line 12, in __init__
    self.db = pymysql.connect(host=host, port=port, user=user, passwd=password, db=db, charset='utf8')
  File "C:\Users\gafel\AppData\Local\Programs\Python\Python39\lib\site-packages\pymysql\connections.py", line 353, in __init__
    self.connect()
  File "C:\Users\gafel\AppData\Local\Programs\Python\Python39\lib\site-packages\pymysql\connections.py", line 664, in connect
    raise exc
pymysql.err.OperationalError: (2003, "Can't connect to MySQL server on 'localhost' ([WinError 10061] Nenhuma conexão pôde ser feita porque a máquina de destino as recusou ativamente)")
2021-06-17: SQL Database reported an error: (2003, "Can't connect to MySQL server on 'localhost' ([WinError 10061] Nenhuma conexão pôde ser feita porque a máquina de destino as recusou ativamente)") 
Traceback (most recent call last):
  File "C:\Users\gafel\AppData\Local\Programs\Python\Python39\lib\site-packages\pymysql\connections.py", line 613, in connect
    sock = socket.create_connection(
  File "C:\Users\gafel\AppData\Local\Programs\Python\Python39\lib\socket.py", line 843, in create_connection
    raise err
  File "C:\Users\gafel\AppData\Local\Programs\Python\Python39\lib\socket.py", line 831, in create_connection
    sock.connect(sa)
ConnectionRefusedError: [WinError 10061] Nenhuma conexão pôde ser feita porque a máquina de destino as recusou ativamente

During handling of the above exception, another exception occurred:

Traceback (most recent call last):
  File "C:\Users\gafel\Documents\GitHub\twittery\src\database\sql\sql.py", line 12, in __init__
    self.db = pymysql.connect(host=host, port=port, user=user, passwd=password, db=db, charset='utf8')
  File "C:\Users\gafel\AppData\Local\Programs\Python\Python39\lib\site-packages\pymysql\connections.py", line 353, in __init__
    self.connect()
  File "C:\Users\gafel\AppData\Local\Programs\Python\Python39\lib\site-packages\pymysql\connections.py", line 664, in connect
    raise exc
pymysql.err.OperationalError: (2003, "Can't connect to MySQL server on 'localhost' ([WinError 10061] Nenhuma conexão pôde ser feita porque a máquina de destino as recusou ativamente)")
2021-06-17: SQL Database reported an error: (2003, "Can't connect to MySQL server on 'localhost' ([WinError 10061] Nenhuma conexão pôde ser feita porque a máquina de destino as recusou ativamente)") 
Traceback (most recent call last):
  File "C:\Users\gafel\AppData\Local\Programs\Python\Python39\lib\site-packages\pymysql\connections.py", line 613, in connect
    sock = socket.create_connection(
  File "C:\Users\gafel\AppData\Local\Programs\Python\Python39\lib\socket.py", line 843, in create_connection
    raise err
  File "C:\Users\gafel\AppData\Local\Programs\Python\Python39\lib\socket.py", line 831, in create_connection
    sock.connect(sa)
ConnectionRefusedError: [WinError 10061] Nenhuma conexão pôde ser feita porque a máquina de destino as recusou ativamente

During handling of the above exception, another exception occurred:

Traceback (most recent call last):
  File "C:\Users\gafel\Documents\GitHub\twittery\src\database\sql\sql.py", line 12, in __init__
    self.db = pymysql.connect(host=host, port=port, user=user, passwd=password, db=db, charset='utf8')
  File "C:\Users\gafel\AppData\Local\Programs\Python\Python39\lib\site-packages\pymysql\connections.py", line 353, in __init__
    self.connect()
  File "C:\Users\gafel\AppData\Local\Programs\Python\Python39\lib\site-packages\pymysql\connections.py", line 664, in connect
    raise exc
pymysql.err.OperationalError: (2003, "Can't connect to MySQL server on 'localhost' ([WinError 10061] Nenhuma conexão pôde ser feita porque a máquina de destino as recusou ativamente)")
2021-06-17: SQL Database reported an error: (2003, "Can't connect to MySQL server on 'localhost' ([WinError 10061] Nenhuma conexão pôde ser feita porque a máquina de destino as recusou ativamente)") 
Traceback (most recent call last):
  File "C:\Users\gafel\AppData\Local\Programs\Python\Python39\lib\site-packages\pymysql\connections.py", line 613, in connect
    sock = socket.create_connection(
  File "C:\Users\gafel\AppData\Local\Programs\Python\Python39\lib\socket.py", line 843, in create_connection
    raise err
  File "C:\Users\gafel\AppData\Local\Programs\Python\Python39\lib\socket.py", line 831, in create_connection
    sock.connect(sa)
ConnectionRefusedError: [WinError 10061] Nenhuma conexão pôde ser feita porque a máquina de destino as recusou ativamente

During handling of the above exception, another exception occurred:

Traceback (most recent call last):
  File "C:\Users\gafel\Documents\GitHub\twittery\src\database\sql\sql.py", line 12, in __init__
    self.db = pymysql.connect(host=host, port=port, user=user, passwd=password, db=db, charset='utf8')
  File "C:\Users\gafel\AppData\Local\Programs\Python\Python39\lib\site-packages\pymysql\connections.py", line 353, in __init__
    self.connect()
  File "C:\Users\gafel\AppData\Local\Programs\Python\Python39\lib\site-packages\pymysql\connections.py", line 664, in connect
    raise exc
pymysql.err.OperationalError: (2003, "Can't connect to MySQL server on 'localhost' ([WinError 10061] Nenhuma conexão pôde ser feita porque a máquina de destino as recusou ativamente)")
2021-06-17: SQL Database reported an error: (2003, "Can't connect to MySQL server on 'localhost' ([WinError 10061] Nenhuma conexão pôde ser feita porque a máquina de destino as recusou ativamente)") 
Traceback (most recent call last):
  File "C:\Users\gafel\AppData\Local\Programs\Python\Python39\lib\site-packages\pymysql\connections.py", line 613, in connect
    sock = socket.create_connection(
  File "C:\Users\gafel\AppData\Local\Programs\Python\Python39\lib\socket.py", line 843, in create_connection
    raise err
  File "C:\Users\gafel\AppData\Local\Programs\Python\Python39\lib\socket.py", line 831, in create_connection
    sock.connect(sa)
ConnectionRefusedError: [WinError 10061] Nenhuma conexão pôde ser feita porque a máquina de destino as recusou ativamente

During handling of the above exception, another exception occurred:

Traceback (most recent call last):
  File "C:\Users\gafel\Documents\GitHub\twittery\src\database\sql\sql.py", line 12, in __init__
    self.db = pymysql.connect(host=host, port=port, user=user, passwd=password, db=db, charset='utf8')
  File "C:\Users\gafel\AppData\Local\Programs\Python\Python39\lib\site-packages\pymysql\connections.py", line 353, in __init__
    self.connect()
  File "C:\Users\gafel\AppData\Local\Programs\Python\Python39\lib\site-packages\pymysql\connections.py", line 664, in connect
    raise exc
pymysql.err.OperationalError: (2003, "Can't connect to MySQL server on 'localhost' ([WinError 10061] Nenhuma conexão pôde ser feita porque a máquina de destino as recusou ativamente)")
2021-06-17: SQL Database reported an error: (2003, "Can't connect to MySQL server on 'localhost' ([WinError 10061] Nenhuma conexão pôde ser feita porque a máquina de destino as recusou ativamente)") 
Traceback (most recent call last):
  File "C:\Users\gafel\AppData\Local\Programs\Python\Python39\lib\site-packages\pymysql\connections.py", line 613, in connect
    sock = socket.create_connection(
  File "C:\Users\gafel\AppData\Local\Programs\Python\Python39\lib\socket.py", line 843, in create_connection
    raise err
  File "C:\Users\gafel\AppData\Local\Programs\Python\Python39\lib\socket.py", line 831, in create_connection
    sock.connect(sa)
ConnectionRefusedError: [WinError 10061] Nenhuma conexão pôde ser feita porque a máquina de destino as recusou ativamente

During handling of the above exception, another exception occurred:

Traceback (most recent call last):
  File "C:\Users\gafel\Documents\GitHub\twittery\src\database\sql\sql.py", line 12, in __init__
    self.db = pymysql.connect(host=host, port=port, user=user, passwd=password, db=db, charset='utf8')
  File "C:\Users\gafel\AppData\Local\Programs\Python\Python39\lib\site-packages\pymysql\connections.py", line 353, in __init__
    self.connect()
  File "C:\Users\gafel\AppData\Local\Programs\Python\Python39\lib\site-packages\pymysql\connections.py", line 664, in connect
    raise exc
pymysql.err.OperationalError: (2003, "Can't connect to MySQL server on 'localhost' ([WinError 10061] Nenhuma conexão pôde ser feita porque a máquina de destino as recusou ativamente)")
2021-06-17: SQL Database reported an error: (2003, "Can't connect to MySQL server on 'localhost' ([WinError 10061] Nenhuma conexão pôde ser feita porque a máquina de destino as recusou ativamente)") 
Traceback (most recent call last):
  File "C:\Users\gafel\AppData\Local\Programs\Python\Python39\lib\site-packages\pymysql\connections.py", line 613, in connect
    sock = socket.create_connection(
  File "C:\Users\gafel\AppData\Local\Programs\Python\Python39\lib\socket.py", line 843, in create_connection
    raise err
  File "C:\Users\gafel\AppData\Local\Programs\Python\Python39\lib\socket.py", line 831, in create_connection
    sock.connect(sa)
ConnectionRefusedError: [WinError 10061] Nenhuma conexão pôde ser feita porque a máquina de destino as recusou ativamente

During handling of the above exception, another exception occurred:

Traceback (most recent call last):
  File "C:\Users\gafel\Documents\GitHub\twittery\src\database\sql\sql.py", line 12, in __init__
    self.db = pymysql.connect(host=host, port=port, user=user, passwd=password, db=db, charset='utf8')
  File "C:\Users\gafel\AppData\Local\Programs\Python\Python39\lib\site-packages\pymysql\connections.py", line 353, in __init__
    self.connect()
  File "C:\Users\gafel\AppData\Local\Programs\Python\Python39\lib\site-packages\pymysql\connections.py", line 664, in connect
    raise exc
pymysql.err.OperationalError: (2003, "Can't connect to MySQL server on 'localhost' ([WinError 10061] Nenhuma conexão pôde ser feita porque a máquina de destino as recusou ativamente)")
2021-06-17: SQL Database reported an error: (2003, "Can't connect to MySQL server on 'localhost' ([WinError 10061] Nenhuma conexão pôde ser feita porque a máquina de destino as recusou ativamente)") 
Traceback (most recent call last):
  File "C:\Users\gafel\AppData\Local\Programs\Python\Python39\lib\site-packages\pymysql\connections.py", line 613, in connect
    sock = socket.create_connection(
  File "C:\Users\gafel\AppData\Local\Programs\Python\Python39\lib\socket.py", line 843, in create_connection
    raise err
  File "C:\Users\gafel\AppData\Local\Programs\Python\Python39\lib\socket.py", line 831, in create_connection
    sock.connect(sa)
ConnectionRefusedError: [WinError 10061] Nenhuma conexão pôde ser feita porque a máquina de destino as recusou ativamente

During handling of the above exception, another exception occurred:

Traceback (most recent call last):
  File "C:\Users\gafel\Documents\GitHub\twittery\src\database\sql\sql.py", line 12, in __init__
    self.db = pymysql.connect(host=host, port=port, user=user, passwd=password, db=db, charset='utf8')
  File "C:\Users\gafel\AppData\Local\Programs\Python\Python39\lib\site-packages\pymysql\connections.py", line 353, in __init__
    self.connect()
  File "C:\Users\gafel\AppData\Local\Programs\Python\Python39\lib\site-packages\pymysql\connections.py", line 664, in connect
    raise exc
pymysql.err.OperationalError: (2003, "Can't connect to MySQL server on 'localhost' ([WinError 10061] Nenhuma conexão pôde ser feita porque a máquina de destino as recusou ativamente)")
2021-06-17: SQL Database reported an error: (2003, "Can't connect to MySQL server on 'localhost' ([WinError 10061] Nenhuma conexão pôde ser feita porque a máquina de destino as recusou ativamente)") 
Traceback (most recent call last):
  File "C:\Users\gafel\AppData\Local\Programs\Python\Python39\lib\site-packages\pymysql\connections.py", line 613, in connect
    sock = socket.create_connection(
  File "C:\Users\gafel\AppData\Local\Programs\Python\Python39\lib\socket.py", line 843, in create_connection
    raise err
  File "C:\Users\gafel\AppData\Local\Programs\Python\Python39\lib\socket.py", line 831, in create_connection
    sock.connect(sa)
ConnectionRefusedError: [WinError 10061] Nenhuma conexão pôde ser feita porque a máquina de destino as recusou ativamente

During handling of the above exception, another exception occurred:

Traceback (most recent call last):
  File "C:\Users\gafel\Documents\GitHub\twittery\src\database\sql\sql.py", line 12, in __init__
    self.db = pymysql.connect(host=host, port=port, user=user, passwd=password, db=db, charset='utf8')
  File "C:\Users\gafel\AppData\Local\Programs\Python\Python39\lib\site-packages\pymysql\connections.py", line 353, in __init__
    self.connect()
  File "C:\Users\gafel\AppData\Local\Programs\Python\Python39\lib\site-packages\pymysql\connections.py", line 664, in connect
    raise exc
pymysql.err.OperationalError: (2003, "Can't connect to MySQL server on 'localhost' ([WinError 10061] Nenhuma conexão pôde ser feita porque a máquina de destino as recusou ativamente)")
2021-06-17: SQL Database reported an error: (2003, "Can't connect to MySQL server on 'localhost' ([WinError 10061] Nenhuma conexão pôde ser feita porque a máquina de destino as recusou ativamente)") 
Traceback (most recent call last):
  File "C:\Users\gafel\AppData\Local\Programs\Python\Python39\lib\site-packages\pymysql\connections.py", line 613, in connect
    sock = socket.create_connection(
  File "C:\Users\gafel\AppData\Local\Programs\Python\Python39\lib\socket.py", line 843, in create_connection
    raise err
  File "C:\Users\gafel\AppData\Local\Programs\Python\Python39\lib\socket.py", line 831, in create_connection
    sock.connect(sa)
ConnectionRefusedError: [WinError 10061] Nenhuma conexão pôde ser feita porque a máquina de destino as recusou ativamente

During handling of the above exception, another exception occurred:

Traceback (most recent call last):
  File "C:\Users\gafel\Documents\GitHub\twittery\src\database\sql\sql.py", line 12, in __init__
    self.db = pymysql.connect(host=host, port=port, user=user, passwd=password, db=db, charset='utf8')
  File "C:\Users\gafel\AppData\Local\Programs\Python\Python39\lib\site-packages\pymysql\connections.py", line 353, in __init__
    self.connect()
  File "C:\Users\gafel\AppData\Local\Programs\Python\Python39\lib\site-packages\pymysql\connections.py", line 664, in connect
    raise exc
pymysql.err.OperationalError: (2003, "Can't connect to MySQL server on 'localhost' ([WinError 10061] Nenhuma conexão pôde ser feita porque a máquina de destino as recusou ativamente)")
2021-06-17: SQL Database reported an error: (2003, "Can't connect to MySQL server on 'localhost' ([WinError 10061] Nenhuma conexão pôde ser feita porque a máquina de destino as recusou ativamente)") 
Traceback (most recent call last):
  File "C:\Users\gafel\AppData\Local\Programs\Python\Python39\lib\site-packages\pymysql\connections.py", line 613, in connect
    sock = socket.create_connection(
  File "C:\Users\gafel\AppData\Local\Programs\Python\Python39\lib\socket.py", line 843, in create_connection
    raise err
  File "C:\Users\gafel\AppData\Local\Programs\Python\Python39\lib\socket.py", line 831, in create_connection
    sock.connect(sa)
ConnectionRefusedError: [WinError 10061] Nenhuma conexão pôde ser feita porque a máquina de destino as recusou ativamente

During handling of the above exception, another exception occurred:

Traceback (most recent call last):
  File "C:\Users\gafel\Documents\GitHub\twittery\src\database\sql\sql.py", line 12, in __init__
    self.db = pymysql.connect(host=host, port=port, user=user, passwd=password, db=db, charset='utf8')
  File "C:\Users\gafel\AppData\Local\Programs\Python\Python39\lib\site-packages\pymysql\connections.py", line 353, in __init__
    self.connect()
  File "C:\Users\gafel\AppData\Local\Programs\Python\Python39\lib\site-packages\pymysql\connections.py", line 664, in connect
    raise exc
pymysql.err.OperationalError: (2003, "Can't connect to MySQL server on 'localhost' ([WinError 10061] Nenhuma conexão pôde ser feita porque a máquina de destino as recusou ativamente)")
2021-06-17: SQL Database reported an error: (2003, "Can't connect to MySQL server on 'localhost' ([WinError 10061] Nenhuma conexão pôde ser feita porque a máquina de destino as recusou ativamente)") 
Traceback (most recent call last):
  File "C:\Users\gafel\AppData\Local\Programs\Python\Python39\lib\site-packages\pymysql\connections.py", line 613, in connect
    sock = socket.create_connection(
  File "C:\Users\gafel\AppData\Local\Programs\Python\Python39\lib\socket.py", line 843, in create_connection
    raise err
  File "C:\Users\gafel\AppData\Local\Programs\Python\Python39\lib\socket.py", line 831, in create_connection
    sock.connect(sa)
ConnectionRefusedError: [WinError 10061] Nenhuma conexão pôde ser feita porque a máquina de destino as recusou ativamente

During handling of the above exception, another exception occurred:

Traceback (most recent call last):
  File "C:\Users\gafel\Documents\GitHub\twittery\src\database\sql\sql.py", line 12, in __init__
    self.db = pymysql.connect(host=host, port=port, user=user, passwd=password, db=db, charset='utf8')
  File "C:\Users\gafel\AppData\Local\Programs\Python\Python39\lib\site-packages\pymysql\connections.py", line 353, in __init__
    self.connect()
  File "C:\Users\gafel\AppData\Local\Programs\Python\Python39\lib\site-packages\pymysql\connections.py", line 664, in connect
    raise exc
pymysql.err.OperationalError: (2003, "Can't connect to MySQL server on 'localhost' ([WinError 10061] Nenhuma conexão pôde ser feita porque a máquina de destino as recusou ativamente)")
2021-06-17: SQL Database reported an error: (2003, "Can't connect to MySQL server on 'localhost' ([WinError 10061] Nenhuma conexão pôde ser feita porque a máquina de destino as recusou ativamente)") 
Traceback (most recent call last):
  File "C:\Users\gafel\AppData\Local\Programs\Python\Python39\lib\site-packages\pymysql\connections.py", line 613, in connect
    sock = socket.create_connection(
  File "C:\Users\gafel\AppData\Local\Programs\Python\Python39\lib\socket.py", line 843, in create_connection
    raise err
  File "C:\Users\gafel\AppData\Local\Programs\Python\Python39\lib\socket.py", line 831, in create_connection
    sock.connect(sa)
ConnectionRefusedError: [WinError 10061] Nenhuma conexão pôde ser feita porque a máquina de destino as recusou ativamente

During handling of the above exception, another exception occurred:

Traceback (most recent call last):
  File "C:\Users\gafel\Documents\GitHub\twittery\src\database\sql\sql.py", line 12, in __init__
    self.db = pymysql.connect(host=host, port=port, user=user, passwd=password, db=db, charset='utf8')
  File "C:\Users\gafel\AppData\Local\Programs\Python\Python39\lib\site-packages\pymysql\connections.py", line 353, in __init__
    self.connect()
  File "C:\Users\gafel\AppData\Local\Programs\Python\Python39\lib\site-packages\pymysql\connections.py", line 664, in connect
    raise exc
pymysql.err.OperationalError: (2003, "Can't connect to MySQL server on 'localhost' ([WinError 10061] Nenhuma conexão pôde ser feita porque a máquina de destino as recusou ativamente)")
2021-06-17: SQL Database reported an error: (2003, "Can't connect to MySQL server on 'localhost' ([WinError 10061] Nenhuma conexão pôde ser feita porque a máquina de destino as recusou ativamente)") 
Traceback (most recent call last):
  File "C:\Users\gafel\AppData\Local\Programs\Python\Python39\lib\site-packages\pymysql\connections.py", line 613, in connect
    sock = socket.create_connection(
  File "C:\Users\gafel\AppData\Local\Programs\Python\Python39\lib\socket.py", line 843, in create_connection
    raise err
  File "C:\Users\gafel\AppData\Local\Programs\Python\Python39\lib\socket.py", line 831, in create_connection
    sock.connect(sa)
ConnectionRefusedError: [WinError 10061] Nenhuma conexão pôde ser feita porque a máquina de destino as recusou ativamente

During handling of the above exception, another exception occurred:

Traceback (most recent call last):
  File "C:\Users\gafel\Documents\GitHub\twittery\src\database\sql\sql.py", line 12, in __init__
    self.db = pymysql.connect(host=host, port=port, user=user, passwd=password, db=db, charset='utf8')
  File "C:\Users\gafel\AppData\Local\Programs\Python\Python39\lib\site-packages\pymysql\connections.py", line 353, in __init__
    self.connect()
  File "C:\Users\gafel\AppData\Local\Programs\Python\Python39\lib\site-packages\pymysql\connections.py", line 664, in connect
    raise exc
pymysql.err.OperationalError: (2003, "Can't connect to MySQL server on 'localhost' ([WinError 10061] Nenhuma conexão pôde ser feita porque a máquina de destino as recusou ativamente)")
2021-06-17: SQL Database reported an error: (2003, "Can't connect to MySQL server on 'localhost' ([WinError 10061] Nenhuma conexão pôde ser feita porque a máquina de destino as recusou ativamente)") 
Traceback (most recent call last):
  File "C:\Users\gafel\AppData\Local\Programs\Python\Python39\lib\site-packages\pymysql\connections.py", line 613, in connect
    sock = socket.create_connection(
  File "C:\Users\gafel\AppData\Local\Programs\Python\Python39\lib\socket.py", line 843, in create_connection
    raise err
  File "C:\Users\gafel\AppData\Local\Programs\Python\Python39\lib\socket.py", line 831, in create_connection
    sock.connect(sa)
ConnectionRefusedError: [WinError 10061] Nenhuma conexão pôde ser feita porque a máquina de destino as recusou ativamente

During handling of the above exception, another exception occurred:

Traceback (most recent call last):
  File "C:\Users\gafel\Documents\GitHub\twittery\src\database\sql\sql.py", line 12, in __init__
    self.db = pymysql.connect(host=host, port=port, user=user, passwd=password, db=db, charset='utf8')
  File "C:\Users\gafel\AppData\Local\Programs\Python\Python39\lib\site-packages\pymysql\connections.py", line 353, in __init__
    self.connect()
  File "C:\Users\gafel\AppData\Local\Programs\Python\Python39\lib\site-packages\pymysql\connections.py", line 664, in connect
    raise exc
pymysql.err.OperationalError: (2003, "Can't connect to MySQL server on 'localhost' ([WinError 10061] Nenhuma conexão pôde ser feita porque a máquina de destino as recusou ativamente)")
2021-06-17: SQL Database reported an error: (2003, "Can't connect to MySQL server on 'localhost' ([WinError 10061] Nenhuma conexão pôde ser feita porque a máquina de destino as recusou ativamente)") 
Traceback (most recent call last):
  File "C:\Users\gafel\AppData\Local\Programs\Python\Python39\lib\site-packages\pymysql\connections.py", line 613, in connect
    sock = socket.create_connection(
  File "C:\Users\gafel\AppData\Local\Programs\Python\Python39\lib\socket.py", line 843, in create_connection
    raise err
  File "C:\Users\gafel\AppData\Local\Programs\Python\Python39\lib\socket.py", line 831, in create_connection
    sock.connect(sa)
ConnectionRefusedError: [WinError 10061] Nenhuma conexão pôde ser feita porque a máquina de destino as recusou ativamente

During handling of the above exception, another exception occurred:

Traceback (most recent call last):
  File "C:\Users\gafel\Documents\GitHub\twittery\src\database\sql\sql.py", line 12, in __init__
    self.db = pymysql.connect(host=host, port=port, user=user, passwd=password, db=db, charset='utf8')
  File "C:\Users\gafel\AppData\Local\Programs\Python\Python39\lib\site-packages\pymysql\connections.py", line 353, in __init__
    self.connect()
  File "C:\Users\gafel\AppData\Local\Programs\Python\Python39\lib\site-packages\pymysql\connections.py", line 664, in connect
    raise exc
pymysql.err.OperationalError: (2003, "Can't connect to MySQL server on 'localhost' ([WinError 10061] Nenhuma conexão pôde ser feita porque a máquina de destino as recusou ativamente)")
2021-06-17: SQL Database reported an error: (2003, "Can't connect to MySQL server on 'localhost' ([WinError 10061] Nenhuma conexão pôde ser feita porque a máquina de destino as recusou ativamente)") 
Traceback (most recent call last):
  File "C:\Users\gafel\AppData\Local\Programs\Python\Python39\lib\site-packages\pymysql\connections.py", line 613, in connect
    sock = socket.create_connection(
  File "C:\Users\gafel\AppData\Local\Programs\Python\Python39\lib\socket.py", line 843, in create_connection
    raise err
  File "C:\Users\gafel\AppData\Local\Programs\Python\Python39\lib\socket.py", line 831, in create_connection
    sock.connect(sa)
ConnectionRefusedError: [WinError 10061] Nenhuma conexão pôde ser feita porque a máquina de destino as recusou ativamente

During handling of the above exception, another exception occurred:

Traceback (most recent call last):
  File "C:\Users\gafel\Documents\GitHub\twittery\src\database\sql\sql.py", line 12, in __init__
    self.db = pymysql.connect(host=host, port=port, user=user, passwd=password, db=db, charset='utf8')
  File "C:\Users\gafel\AppData\Local\Programs\Python\Python39\lib\site-packages\pymysql\connections.py", line 353, in __init__
    self.connect()
  File "C:\Users\gafel\AppData\Local\Programs\Python\Python39\lib\site-packages\pymysql\connections.py", line 664, in connect
    raise exc
pymysql.err.OperationalError: (2003, "Can't connect to MySQL server on 'localhost' ([WinError 10061] Nenhuma conexão pôde ser feita porque a máquina de destino as recusou ativamente)")
2021-06-17: SQL Database reported an error: (2003, "Can't connect to MySQL server on 'localhost' ([WinError 10061] Nenhuma conexão pôde ser feita porque a máquina de destino as recusou ativamente)") 
Traceback (most recent call last):
  File "C:\Users\gafel\AppData\Local\Programs\Python\Python39\lib\site-packages\pymysql\connections.py", line 613, in connect
    sock = socket.create_connection(
  File "C:\Users\gafel\AppData\Local\Programs\Python\Python39\lib\socket.py", line 843, in create_connection
    raise err
  File "C:\Users\gafel\AppData\Local\Programs\Python\Python39\lib\socket.py", line 831, in create_connection
    sock.connect(sa)
ConnectionRefusedError: [WinError 10061] Nenhuma conexão pôde ser feita porque a máquina de destino as recusou ativamente

During handling of the above exception, another exception occurred:

Traceback (most recent call last):
  File "C:\Users\gafel\Documents\GitHub\twittery\src\database\sql\sql.py", line 12, in __init__
    self.db = pymysql.connect(host=host, port=port, user=user, passwd=password, db=db, charset='utf8')
  File "C:\Users\gafel\AppData\Local\Programs\Python\Python39\lib\site-packages\pymysql\connections.py", line 353, in __init__
    self.connect()
  File "C:\Users\gafel\AppData\Local\Programs\Python\Python39\lib\site-packages\pymysql\connections.py", line 664, in connect
    raise exc
pymysql.err.OperationalError: (2003, "Can't connect to MySQL server on 'localhost' ([WinError 10061] Nenhuma conexão pôde ser feita porque a máquina de destino as recusou ativamente)")
2021-06-17: SQL Database reported an error: (2003, "Can't connect to MySQL server on 'localhost' ([WinError 10061] Nenhuma conexão pôde ser feita porque a máquina de destino as recusou ativamente)") 
Traceback (most recent call last):
  File "C:\Users\gafel\AppData\Local\Programs\Python\Python39\lib\site-packages\pymysql\connections.py", line 613, in connect
    sock = socket.create_connection(
  File "C:\Users\gafel\AppData\Local\Programs\Python\Python39\lib\socket.py", line 843, in create_connection
    raise err
  File "C:\Users\gafel\AppData\Local\Programs\Python\Python39\lib\socket.py", line 831, in create_connection
    sock.connect(sa)
ConnectionRefusedError: [WinError 10061] Nenhuma conexão pôde ser feita porque a máquina de destino as recusou ativamente

During handling of the above exception, another exception occurred:

Traceback (most recent call last):
  File "C:\Users\gafel\Documents\GitHub\twittery\src\database\sql\sql.py", line 12, in __init__
    self.db = pymysql.connect(host=host, port=port, user=user, passwd=password, db=db, charset='utf8')
  File "C:\Users\gafel\AppData\Local\Programs\Python\Python39\lib\site-packages\pymysql\connections.py", line 353, in __init__
    self.connect()
  File "C:\Users\gafel\AppData\Local\Programs\Python\Python39\lib\site-packages\pymysql\connections.py", line 664, in connect
    raise exc
pymysql.err.OperationalError: (2003, "Can't connect to MySQL server on 'localhost' ([WinError 10061] Nenhuma conexão pôde ser feita porque a máquina de destino as recusou ativamente)")
2021-06-17: SQL Database reported an error: (2003, "Can't connect to MySQL server on 'localhost' ([WinError 10061] Nenhuma conexão pôde ser feita porque a máquina de destino as recusou ativamente)") 
Traceback (most recent call last):
  File "C:\Users\gafel\AppData\Local\Programs\Python\Python39\lib\site-packages\pymysql\connections.py", line 613, in connect
    sock = socket.create_connection(
  File "C:\Users\gafel\AppData\Local\Programs\Python\Python39\lib\socket.py", line 843, in create_connection
    raise err
  File "C:\Users\gafel\AppData\Local\Programs\Python\Python39\lib\socket.py", line 831, in create_connection
    sock.connect(sa)
ConnectionRefusedError: [WinError 10061] Nenhuma conexão pôde ser feita porque a máquina de destino as recusou ativamente

During handling of the above exception, another exception occurred:

Traceback (most recent call last):
  File "C:\Users\gafel\Documents\GitHub\twittery\src\database\sql\sql.py", line 12, in __init__
    self.db = pymysql.connect(host=host, port=port, user=user, passwd=password, db=db, charset='utf8')
  File "C:\Users\gafel\AppData\Local\Programs\Python\Python39\lib\site-packages\pymysql\connections.py", line 353, in __init__
    self.connect()
  File "C:\Users\gafel\AppData\Local\Programs\Python\Python39\lib\site-packages\pymysql\connections.py", line 664, in connect
    raise exc
pymysql.err.OperationalError: (2003, "Can't connect to MySQL server on 'localhost' ([WinError 10061] Nenhuma conexão pôde ser feita porque a máquina de destino as recusou ativamente)")
2021-06-17: SQL Database reported an error: (2003, "Can't connect to MySQL server on 'localhost' ([WinError 10061] Nenhuma conexão pôde ser feita porque a máquina de destino as recusou ativamente)") 
Traceback (most recent call last):
  File "C:\Users\gafel\AppData\Local\Programs\Python\Python39\lib\site-packages\pymysql\connections.py", line 613, in connect
    sock = socket.create_connection(
  File "C:\Users\gafel\AppData\Local\Programs\Python\Python39\lib\socket.py", line 843, in create_connection
    raise err
  File "C:\Users\gafel\AppData\Local\Programs\Python\Python39\lib\socket.py", line 831, in create_connection
    sock.connect(sa)
ConnectionRefusedError: [WinError 10061] Nenhuma conexão pôde ser feita porque a máquina de destino as recusou ativamente

During handling of the above exception, another exception occurred:

Traceback (most recent call last):
  File "C:\Users\gafel\Documents\GitHub\twittery\src\database\sql\sql.py", line 12, in __init__
    self.db = pymysql.connect(host=host, port=port, user=user, passwd=password, db=db, charset='utf8')
  File "C:\Users\gafel\AppData\Local\Programs\Python\Python39\lib\site-packages\pymysql\connections.py", line 353, in __init__
    self.connect()
  File "C:\Users\gafel\AppData\Local\Programs\Python\Python39\lib\site-packages\pymysql\connections.py", line 664, in connect
    raise exc
pymysql.err.OperationalError: (2003, "Can't connect to MySQL server on 'localhost' ([WinError 10061] Nenhuma conexão pôde ser feita porque a máquina de destino as recusou ativamente)")
2021-06-17: SQL Database reported an error: (2003, "Can't connect to MySQL server on 'localhost' ([WinError 10061] Nenhuma conexão pôde ser feita porque a máquina de destino as recusou ativamente)") 
Traceback (most recent call last):
  File "C:\Users\gafel\AppData\Local\Programs\Python\Python39\lib\site-packages\pymysql\connections.py", line 613, in connect
    sock = socket.create_connection(
  File "C:\Users\gafel\AppData\Local\Programs\Python\Python39\lib\socket.py", line 843, in create_connection
    raise err
  File "C:\Users\gafel\AppData\Local\Programs\Python\Python39\lib\socket.py", line 831, in create_connection
    sock.connect(sa)
ConnectionRefusedError: [WinError 10061] Nenhuma conexão pôde ser feita porque a máquina de destino as recusou ativamente

During handling of the above exception, another exception occurred:

Traceback (most recent call last):
  File "C:\Users\gafel\Documents\GitHub\twittery\src\database\sql\sql.py", line 12, in __init__
    self.db = pymysql.connect(host=host, port=port, user=user, passwd=password, db=db, charset='utf8')
  File "C:\Users\gafel\AppData\Local\Programs\Python\Python39\lib\site-packages\pymysql\connections.py", line 353, in __init__
    self.connect()
  File "C:\Users\gafel\AppData\Local\Programs\Python\Python39\lib\site-packages\pymysql\connections.py", line 664, in connect
    raise exc
pymysql.err.OperationalError: (2003, "Can't connect to MySQL server on 'localhost' ([WinError 10061] Nenhuma conexão pôde ser feita porque a máquina de destino as recusou ativamente)")
2021-06-17: SQL Database reported an error: (2003, "Can't connect to MySQL server on 'localhost' ([WinError 10061] Nenhuma conexão pôde ser feita porque a máquina de destino as recusou ativamente)") 
Traceback (most recent call last):
  File "C:\Users\gafel\AppData\Local\Programs\Python\Python39\lib\site-packages\pymysql\connections.py", line 613, in connect
    sock = socket.create_connection(
  File "C:\Users\gafel\AppData\Local\Programs\Python\Python39\lib\socket.py", line 843, in create_connection
    raise err
  File "C:\Users\gafel\AppData\Local\Programs\Python\Python39\lib\socket.py", line 831, in create_connection
    sock.connect(sa)
ConnectionRefusedError: [WinError 10061] Nenhuma conexão pôde ser feita porque a máquina de destino as recusou ativamente

During handling of the above exception, another exception occurred:

Traceback (most recent call last):
  File "C:\Users\gafel\Documents\GitHub\twittery\src\database\sql\sql.py", line 12, in __init__
    self.db = pymysql.connect(host=host, port=port, user=user, passwd=password, db=db, charset='utf8')
  File "C:\Users\gafel\AppData\Local\Programs\Python\Python39\lib\site-packages\pymysql\connections.py", line 353, in __init__
    self.connect()
  File "C:\Users\gafel\AppData\Local\Programs\Python\Python39\lib\site-packages\pymysql\connections.py", line 664, in connect
    raise exc
pymysql.err.OperationalError: (2003, "Can't connect to MySQL server on 'localhost' ([WinError 10061] Nenhuma conexão pôde ser feita porque a máquina de destino as recusou ativamente)")
2021-06-17: SQL Database reported an error: (2003, "Can't connect to MySQL server on 'localhost' ([WinError 10061] Nenhuma conexão pôde ser feita porque a máquina de destino as recusou ativamente)") 
Traceback (most recent call last):
  File "C:\Users\gafel\AppData\Local\Programs\Python\Python39\lib\site-packages\pymysql\connections.py", line 613, in connect
    sock = socket.create_connection(
  File "C:\Users\gafel\AppData\Local\Programs\Python\Python39\lib\socket.py", line 843, in create_connection
    raise err
  File "C:\Users\gafel\AppData\Local\Programs\Python\Python39\lib\socket.py", line 831, in create_connection
    sock.connect(sa)
ConnectionRefusedError: [WinError 10061] Nenhuma conexão pôde ser feita porque a máquina de destino as recusou ativamente

During handling of the above exception, another exception occurred:

Traceback (most recent call last):
  File "C:\Users\gafel\Documents\GitHub\twittery\src\database\sql\sql.py", line 12, in __init__
    self.db = pymysql.connect(host=host, port=port, user=user, passwd=password, db=db, charset='utf8')
  File "C:\Users\gafel\AppData\Local\Programs\Python\Python39\lib\site-packages\pymysql\connections.py", line 353, in __init__
    self.connect()
  File "C:\Users\gafel\AppData\Local\Programs\Python\Python39\lib\site-packages\pymysql\connections.py", line 664, in connect
    raise exc
pymysql.err.OperationalError: (2003, "Can't connect to MySQL server on 'localhost' ([WinError 10061] Nenhuma conexão pôde ser feita porque a máquina de destino as recusou ativamente)")
2021-06-17: SQL Database reported an error: (2003, "Can't connect to MySQL server on 'localhost' ([WinError 10061] Nenhuma conexão pôde ser feita porque a máquina de destino as recusou ativamente)") 
Traceback (most recent call last):
  File "C:\Users\gafel\AppData\Local\Programs\Python\Python39\lib\site-packages\pymysql\connections.py", line 613, in connect
    sock = socket.create_connection(
  File "C:\Users\gafel\AppData\Local\Programs\Python\Python39\lib\socket.py", line 843, in create_connection
    raise err
  File "C:\Users\gafel\AppData\Local\Programs\Python\Python39\lib\socket.py", line 831, in create_connection
    sock.connect(sa)
ConnectionRefusedError: [WinError 10061] Nenhuma conexão pôde ser feita porque a máquina de destino as recusou ativamente

During handling of the above exception, another exception occurred:

Traceback (most recent call last):
  File "C:\Users\gafel\Documents\GitHub\twittery\src\database\sql\sql.py", line 12, in __init__
    self.db = pymysql.connect(host=host, port=port, user=user, passwd=password, db=db, charset='utf8')
  File "C:\Users\gafel\AppData\Local\Programs\Python\Python39\lib\site-packages\pymysql\connections.py", line 353, in __init__
    self.connect()
  File "C:\Users\gafel\AppData\Local\Programs\Python\Python39\lib\site-packages\pymysql\connections.py", line 664, in connect
    raise exc
pymysql.err.OperationalError: (2003, "Can't connect to MySQL server on 'localhost' ([WinError 10061] Nenhuma conexão pôde ser feita porque a máquina de destino as recusou ativamente)")
2021-06-17: SQL Database reported an error: (2003, "Can't connect to MySQL server on 'localhost' ([WinError 10061] Nenhuma conexão pôde ser feita porque a máquina de destino as recusou ativamente)") 
Traceback (most recent call last):
  File "C:\Users\gafel\AppData\Local\Programs\Python\Python39\lib\site-packages\pymysql\connections.py", line 613, in connect
    sock = socket.create_connection(
  File "C:\Users\gafel\AppData\Local\Programs\Python\Python39\lib\socket.py", line 843, in create_connection
    raise err
  File "C:\Users\gafel\AppData\Local\Programs\Python\Python39\lib\socket.py", line 831, in create_connection
    sock.connect(sa)
ConnectionRefusedError: [WinError 10061] Nenhuma conexão pôde ser feita porque a máquina de destino as recusou ativamente

During handling of the above exception, another exception occurred:

Traceback (most recent call last):
  File "C:\Users\gafel\Documents\GitHub\twittery\src\database\sql\sql.py", line 12, in __init__
    self.db = pymysql.connect(host=host, port=port, user=user, passwd=password, db=db, charset='utf8')
  File "C:\Users\gafel\AppData\Local\Programs\Python\Python39\lib\site-packages\pymysql\connections.py", line 353, in __init__
    self.connect()
  File "C:\Users\gafel\AppData\Local\Programs\Python\Python39\lib\site-packages\pymysql\connections.py", line 664, in connect
    raise exc
pymysql.err.OperationalError: (2003, "Can't connect to MySQL server on 'localhost' ([WinError 10061] Nenhuma conexão pôde ser feita porque a máquina de destino as recusou ativamente)")
2021-06-17: SQL Database reported an error: (2003, "Can't connect to MySQL server on 'localhost' ([WinError 10061] Nenhuma conexão pôde ser feita porque a máquina de destino as recusou ativamente)") 
Traceback (most recent call last):
  File "C:\Users\gafel\AppData\Local\Programs\Python\Python39\lib\site-packages\pymysql\connections.py", line 613, in connect
    sock = socket.create_connection(
  File "C:\Users\gafel\AppData\Local\Programs\Python\Python39\lib\socket.py", line 843, in create_connection
    raise err
  File "C:\Users\gafel\AppData\Local\Programs\Python\Python39\lib\socket.py", line 831, in create_connection
    sock.connect(sa)
ConnectionRefusedError: [WinError 10061] Nenhuma conexão pôde ser feita porque a máquina de destino as recusou ativamente

During handling of the above exception, another exception occurred:

Traceback (most recent call last):
  File "C:\Users\gafel\Documents\GitHub\twittery\src\database\sql\sql.py", line 12, in __init__
    self.db = pymysql.connect(host=host, port=port, user=user, passwd=password, db=db, charset='utf8')
  File "C:\Users\gafel\AppData\Local\Programs\Python\Python39\lib\site-packages\pymysql\connections.py", line 353, in __init__
    self.connect()
  File "C:\Users\gafel\AppData\Local\Programs\Python\Python39\lib\site-packages\pymysql\connections.py", line 664, in connect
    raise exc
pymysql.err.OperationalError: (2003, "Can't connect to MySQL server on 'localhost' ([WinError 10061] Nenhuma conexão pôde ser feita porque a máquina de destino as recusou ativamente)")
2021-06-17: SQL Database reported an error: (2003, "Can't connect to MySQL server on 'localhost' ([WinError 10061] Nenhuma conexão pôde ser feita porque a máquina de destino as recusou ativamente)") 
Traceback (most recent call last):
  File "C:\Users\gafel\AppData\Local\Programs\Python\Python39\lib\site-packages\pymysql\connections.py", line 613, in connect
    sock = socket.create_connection(
  File "C:\Users\gafel\AppData\Local\Programs\Python\Python39\lib\socket.py", line 843, in create_connection
    raise err
  File "C:\Users\gafel\AppData\Local\Programs\Python\Python39\lib\socket.py", line 831, in create_connection
    sock.connect(sa)
ConnectionRefusedError: [WinError 10061] Nenhuma conexão pôde ser feita porque a máquina de destino as recusou ativamente

During handling of the above exception, another exception occurred:

Traceback (most recent call last):
  File "C:\Users\gafel\Documents\GitHub\twittery\src\database\sql\sql.py", line 12, in __init__
    self.db = pymysql.connect(host=host, port=port, user=user, passwd=password, db=db, charset='utf8')
  File "C:\Users\gafel\AppData\Local\Programs\Python\Python39\lib\site-packages\pymysql\connections.py", line 353, in __init__
    self.connect()
  File "C:\Users\gafel\AppData\Local\Programs\Python\Python39\lib\site-packages\pymysql\connections.py", line 664, in connect
    raise exc
pymysql.err.OperationalError: (2003, "Can't connect to MySQL server on 'localhost' ([WinError 10061] Nenhuma conexão pôde ser feita porque a máquina de destino as recusou ativamente)")
2021-06-17: SQL Database reported an error: (2003, "Can't connect to MySQL server on 'localhost' ([WinError 10061] Nenhuma conexão pôde ser feita porque a máquina de destino as recusou ativamente)") 
Traceback (most recent call last):
  File "C:\Users\gafel\AppData\Local\Programs\Python\Python39\lib\site-packages\pymysql\connections.py", line 613, in connect
    sock = socket.create_connection(
  File "C:\Users\gafel\AppData\Local\Programs\Python\Python39\lib\socket.py", line 843, in create_connection
    raise err
  File "C:\Users\gafel\AppData\Local\Programs\Python\Python39\lib\socket.py", line 831, in create_connection
    sock.connect(sa)
ConnectionRefusedError: [WinError 10061] Nenhuma conexão pôde ser feita porque a máquina de destino as recusou ativamente

During handling of the above exception, another exception occurred:

Traceback (most recent call last):
  File "C:\Users\gafel\Documents\GitHub\twittery\src\database\sql\sql.py", line 12, in __init__
    self.db = pymysql.connect(host=host, port=port, user=user, passwd=password, db=db, charset='utf8')
  File "C:\Users\gafel\AppData\Local\Programs\Python\Python39\lib\site-packages\pymysql\connections.py", line 353, in __init__
    self.connect()
  File "C:\Users\gafel\AppData\Local\Programs\Python\Python39\lib\site-packages\pymysql\connections.py", line 664, in connect
    raise exc
pymysql.err.OperationalError: (2003, "Can't connect to MySQL server on 'localhost' ([WinError 10061] Nenhuma conexão pôde ser feita porque a máquina de destino as recusou ativamente)")
2021-06-17: SQL Database reported an error: (2003, "Can't connect to MySQL server on 'localhost' ([WinError 10061] Nenhuma conexão pôde ser feita porque a máquina de destino as recusou ativamente)") 
Traceback (most recent call last):
  File "C:\Users\gafel\AppData\Local\Programs\Python\Python39\lib\site-packages\pymysql\connections.py", line 613, in connect
    sock = socket.create_connection(
  File "C:\Users\gafel\AppData\Local\Programs\Python\Python39\lib\socket.py", line 843, in create_connection
    raise err
  File "C:\Users\gafel\AppData\Local\Programs\Python\Python39\lib\socket.py", line 831, in create_connection
    sock.connect(sa)
ConnectionRefusedError: [WinError 10061] Nenhuma conexão pôde ser feita porque a máquina de destino as recusou ativamente

During handling of the above exception, another exception occurred:

Traceback (most recent call last):
  File "C:\Users\gafel\Documents\GitHub\twittery\src\database\sql\sql.py", line 12, in __init__
    self.db = pymysql.connect(host=host, port=port, user=user, passwd=password, db=db, charset='utf8')
  File "C:\Users\gafel\AppData\Local\Programs\Python\Python39\lib\site-packages\pymysql\connections.py", line 353, in __init__
    self.connect()
  File "C:\Users\gafel\AppData\Local\Programs\Python\Python39\lib\site-packages\pymysql\connections.py", line 664, in connect
    raise exc
pymysql.err.OperationalError: (2003, "Can't connect to MySQL server on 'localhost' ([WinError 10061] Nenhuma conexão pôde ser feita porque a máquina de destino as recusou ativamente)")
2021-06-17: SQL Database reported an error: (2003, "Can't connect to MySQL server on 'localhost' ([WinError 10061] Nenhuma conexão pôde ser feita porque a máquina de destino as recusou ativamente)") 
Traceback (most recent call last):
  File "C:\Users\gafel\AppData\Local\Programs\Python\Python39\lib\site-packages\pymysql\connections.py", line 613, in connect
    sock = socket.create_connection(
  File "C:\Users\gafel\AppData\Local\Programs\Python\Python39\lib\socket.py", line 843, in create_connection
    raise err
  File "C:\Users\gafel\AppData\Local\Programs\Python\Python39\lib\socket.py", line 831, in create_connection
    sock.connect(sa)
ConnectionRefusedError: [WinError 10061] Nenhuma conexão pôde ser feita porque a máquina de destino as recusou ativamente

During handling of the above exception, another exception occurred:

Traceback (most recent call last):
  File "C:\Users\gafel\Documents\GitHub\twittery\src\database\sql\sql.py", line 12, in __init__
    self.db = pymysql.connect(host=host, port=port, user=user, passwd=password, db=db, charset='utf8')
  File "C:\Users\gafel\AppData\Local\Programs\Python\Python39\lib\site-packages\pymysql\connections.py", line 353, in __init__
    self.connect()
  File "C:\Users\gafel\AppData\Local\Programs\Python\Python39\lib\site-packages\pymysql\connections.py", line 664, in connect
    raise exc
pymysql.err.OperationalError: (2003, "Can't connect to MySQL server on 'localhost' ([WinError 10061] Nenhuma conexão pôde ser feita porque a máquina de destino as recusou ativamente)")
2021-06-17: SQL Database reported an error: (2003, "Can't connect to MySQL server on 'localhost' ([WinError 10061] Nenhuma conexão pôde ser feita porque a máquina de destino as recusou ativamente)") 
Traceback (most recent call last):
  File "C:\Users\gafel\AppData\Local\Programs\Python\Python39\lib\site-packages\pymysql\connections.py", line 613, in connect
    sock = socket.create_connection(
  File "C:\Users\gafel\AppData\Local\Programs\Python\Python39\lib\socket.py", line 843, in create_connection
    raise err
  File "C:\Users\gafel\AppData\Local\Programs\Python\Python39\lib\socket.py", line 831, in create_connection
    sock.connect(sa)
ConnectionRefusedError: [WinError 10061] Nenhuma conexão pôde ser feita porque a máquina de destino as recusou ativamente

During handling of the above exception, another exception occurred:

Traceback (most recent call last):
  File "C:\Users\gafel\Documents\GitHub\twittery\src\database\sql\sql.py", line 12, in __init__
    self.db = pymysql.connect(host=host, port=port, user=user, passwd=password, db=db, charset='utf8')
  File "C:\Users\gafel\AppData\Local\Programs\Python\Python39\lib\site-packages\pymysql\connections.py", line 353, in __init__
    self.connect()
  File "C:\Users\gafel\AppData\Local\Programs\Python\Python39\lib\site-packages\pymysql\connections.py", line 664, in connect
    raise exc
pymysql.err.OperationalError: (2003, "Can't connect to MySQL server on 'localhost' ([WinError 10061] Nenhuma conexão pôde ser feita porque a máquina de destino as recusou ativamente)")
2021-06-17: SQL Database reported an error: (2003, "Can't connect to MySQL server on 'localhost' ([WinError 10061] Nenhuma conexão pôde ser feita porque a máquina de destino as recusou ativamente)") 
Traceback (most recent call last):
  File "C:\Users\gafel\AppData\Local\Programs\Python\Python39\lib\site-packages\pymysql\connections.py", line 613, in connect
    sock = socket.create_connection(
  File "C:\Users\gafel\AppData\Local\Programs\Python\Python39\lib\socket.py", line 843, in create_connection
    raise err
  File "C:\Users\gafel\AppData\Local\Programs\Python\Python39\lib\socket.py", line 831, in create_connection
    sock.connect(sa)
ConnectionRefusedError: [WinError 10061] Nenhuma conexão pôde ser feita porque a máquina de destino as recusou ativamente

During handling of the above exception, another exception occurred:

Traceback (most recent call last):
  File "C:\Users\gafel\Documents\GitHub\twittery\src\database\sql\sql.py", line 12, in __init__
    self.db = pymysql.connect(host=host, port=port, user=user, passwd=password, db=db, charset='utf8')
  File "C:\Users\gafel\AppData\Local\Programs\Python\Python39\lib\site-packages\pymysql\connections.py", line 353, in __init__
    self.connect()
  File "C:\Users\gafel\AppData\Local\Programs\Python\Python39\lib\site-packages\pymysql\connections.py", line 664, in connect
    raise exc
pymysql.err.OperationalError: (2003, "Can't connect to MySQL server on 'localhost' ([WinError 10061] Nenhuma conexão pôde ser feita porque a máquina de destino as recusou ativamente)")
2021-06-17: SQL Database reported an error: (2003, "Can't connect to MySQL server on 'localhost' ([WinError 10061] Nenhuma conexão pôde ser feita porque a máquina de destino as recusou ativamente)") 
Traceback (most recent call last):
  File "C:\Users\gafel\AppData\Local\Programs\Python\Python39\lib\site-packages\pymysql\connections.py", line 613, in connect
    sock = socket.create_connection(
  File "C:\Users\gafel\AppData\Local\Programs\Python\Python39\lib\socket.py", line 843, in create_connection
    raise err
  File "C:\Users\gafel\AppData\Local\Programs\Python\Python39\lib\socket.py", line 831, in create_connection
    sock.connect(sa)
ConnectionRefusedError: [WinError 10061] Nenhuma conexão pôde ser feita porque a máquina de destino as recusou ativamente

During handling of the above exception, another exception occurred:

Traceback (most recent call last):
  File "C:\Users\gafel\Documents\GitHub\twittery\src\database\sql\sql.py", line 12, in __init__
    self.db = pymysql.connect(host=host, port=port, user=user, passwd=password, db=db, charset='utf8')
  File "C:\Users\gafel\AppData\Local\Programs\Python\Python39\lib\site-packages\pymysql\connections.py", line 353, in __init__
    self.connect()
  File "C:\Users\gafel\AppData\Local\Programs\Python\Python39\lib\site-packages\pymysql\connections.py", line 664, in connect
    raise exc
pymysql.err.OperationalError: (2003, "Can't connect to MySQL server on 'localhost' ([WinError 10061] Nenhuma conexão pôde ser feita porque a máquina de destino as recusou ativamente)")
2021-06-17: SQL Database reported an error: (2003, "Can't connect to MySQL server on 'localhost' ([WinError 10061] Nenhuma conexão pôde ser feita porque a máquina de destino as recusou ativamente)") 
Traceback (most recent call last):
  File "C:\Users\gafel\AppData\Local\Programs\Python\Python39\lib\site-packages\pymysql\connections.py", line 613, in connect
    sock = socket.create_connection(
  File "C:\Users\gafel\AppData\Local\Programs\Python\Python39\lib\socket.py", line 843, in create_connection
    raise err
  File "C:\Users\gafel\AppData\Local\Programs\Python\Python39\lib\socket.py", line 831, in create_connection
    sock.connect(sa)
ConnectionRefusedError: [WinError 10061] Nenhuma conexão pôde ser feita porque a máquina de destino as recusou ativamente

During handling of the above exception, another exception occurred:

Traceback (most recent call last):
  File "C:\Users\gafel\Documents\GitHub\twittery\src\database\sql\sql.py", line 12, in __init__
    self.db = pymysql.connect(host=host, port=port, user=user, passwd=password, db=db, charset='utf8')
  File "C:\Users\gafel\AppData\Local\Programs\Python\Python39\lib\site-packages\pymysql\connections.py", line 353, in __init__
    self.connect()
  File "C:\Users\gafel\AppData\Local\Programs\Python\Python39\lib\site-packages\pymysql\connections.py", line 664, in connect
    raise exc
pymysql.err.OperationalError: (2003, "Can't connect to MySQL server on 'localhost' ([WinError 10061] Nenhuma conexão pôde ser feita porque a máquina de destino as recusou ativamente)")
2021-06-17: SQL Database reported an error: (2003, "Can't connect to MySQL server on 'localhost' ([WinError 10061] Nenhuma conexão pôde ser feita porque a máquina de destino as recusou ativamente)") 
Traceback (most recent call last):
  File "C:\Users\gafel\AppData\Local\Programs\Python\Python39\lib\site-packages\pymysql\connections.py", line 613, in connect
    sock = socket.create_connection(
  File "C:\Users\gafel\AppData\Local\Programs\Python\Python39\lib\socket.py", line 843, in create_connection
    raise err
  File "C:\Users\gafel\AppData\Local\Programs\Python\Python39\lib\socket.py", line 831, in create_connection
    sock.connect(sa)
ConnectionRefusedError: [WinError 10061] Nenhuma conexão pôde ser feita porque a máquina de destino as recusou ativamente

During handling of the above exception, another exception occurred:

Traceback (most recent call last):
  File "C:\Users\gafel\Documents\GitHub\twittery\src\database\sql\sql.py", line 12, in __init__
    self.db = pymysql.connect(host=host, port=port, user=user, passwd=password, db=db, charset='utf8')
  File "C:\Users\gafel\AppData\Local\Programs\Python\Python39\lib\site-packages\pymysql\connections.py", line 353, in __init__
    self.connect()
  File "C:\Users\gafel\AppData\Local\Programs\Python\Python39\lib\site-packages\pymysql\connections.py", line 664, in connect
    raise exc
pymysql.err.OperationalError: (2003, "Can't connect to MySQL server on 'localhost' ([WinError 10061] Nenhuma conexão pôde ser feita porque a máquina de destino as recusou ativamente)")
2021-06-17: SQL Database reported an error: (2003, "Can't connect to MySQL server on 'localhost' ([WinError 10061] Nenhuma conexão pôde ser feita porque a máquina de destino as recusou ativamente)") 
Traceback (most recent call last):
  File "C:\Users\gafel\AppData\Local\Programs\Python\Python39\lib\site-packages\pymysql\connections.py", line 613, in connect
    sock = socket.create_connection(
  File "C:\Users\gafel\AppData\Local\Programs\Python\Python39\lib\socket.py", line 843, in create_connection
    raise err
  File "C:\Users\gafel\AppData\Local\Programs\Python\Python39\lib\socket.py", line 831, in create_connection
    sock.connect(sa)
ConnectionRefusedError: [WinError 10061] Nenhuma conexão pôde ser feita porque a máquina de destino as recusou ativamente

During handling of the above exception, another exception occurred:

Traceback (most recent call last):
  File "C:\Users\gafel\Documents\GitHub\twittery\src\database\sql\sql.py", line 12, in __init__
    self.db = pymysql.connect(host=host, port=port, user=user, passwd=password, db=db, charset='utf8')
  File "C:\Users\gafel\AppData\Local\Programs\Python\Python39\lib\site-packages\pymysql\connections.py", line 353, in __init__
    self.connect()
  File "C:\Users\gafel\AppData\Local\Programs\Python\Python39\lib\site-packages\pymysql\connections.py", line 664, in connect
    raise exc
pymysql.err.OperationalError: (2003, "Can't connect to MySQL server on 'localhost' ([WinError 10061] Nenhuma conexão pôde ser feita porque a máquina de destino as recusou ativamente)")
2021-06-17: SQL Database reported an error: (2003, "Can't connect to MySQL server on 'localhost' ([WinError 10061] Nenhuma conexão pôde ser feita porque a máquina de destino as recusou ativamente)") 
Traceback (most recent call last):
  File "C:\Users\gafel\AppData\Local\Programs\Python\Python39\lib\site-packages\pymysql\connections.py", line 613, in connect
    sock = socket.create_connection(
  File "C:\Users\gafel\AppData\Local\Programs\Python\Python39\lib\socket.py", line 843, in create_connection
    raise err
  File "C:\Users\gafel\AppData\Local\Programs\Python\Python39\lib\socket.py", line 831, in create_connection
    sock.connect(sa)
ConnectionRefusedError: [WinError 10061] Nenhuma conexão pôde ser feita porque a máquina de destino as recusou ativamente

During handling of the above exception, another exception occurred:

Traceback (most recent call last):
  File "C:\Users\gafel\Documents\GitHub\twittery\src\database\sql\sql.py", line 12, in __init__
    self.db = pymysql.connect(host=host, port=port, user=user, passwd=password, db=db, charset='utf8')
  File "C:\Users\gafel\AppData\Local\Programs\Python\Python39\lib\site-packages\pymysql\connections.py", line 353, in __init__
    self.connect()
  File "C:\Users\gafel\AppData\Local\Programs\Python\Python39\lib\site-packages\pymysql\connections.py", line 664, in connect
    raise exc
pymysql.err.OperationalError: (2003, "Can't connect to MySQL server on 'localhost' ([WinError 10061] Nenhuma conexão pôde ser feita porque a máquina de destino as recusou ativamente)")
2021-06-17: SQL Database reported an error: (2003, "Can't connect to MySQL server on 'localhost' ([WinError 10061] Nenhuma conexão pôde ser feita porque a máquina de destino as recusou ativamente)") 
Traceback (most recent call last):
  File "C:\Users\gafel\AppData\Local\Programs\Python\Python39\lib\site-packages\pymysql\connections.py", line 613, in connect
    sock = socket.create_connection(
  File "C:\Users\gafel\AppData\Local\Programs\Python\Python39\lib\socket.py", line 843, in create_connection
    raise err
  File "C:\Users\gafel\AppData\Local\Programs\Python\Python39\lib\socket.py", line 831, in create_connection
    sock.connect(sa)
ConnectionRefusedError: [WinError 10061] Nenhuma conexão pôde ser feita porque a máquina de destino as recusou ativamente

During handling of the above exception, another exception occurred:

Traceback (most recent call last):
  File "C:\Users\gafel\Documents\GitHub\twittery\src\database\sql\sql.py", line 12, in __init__
    self.db = pymysql.connect(host=host, port=port, user=user, passwd=password, db=db, charset='utf8')
  File "C:\Users\gafel\AppData\Local\Programs\Python\Python39\lib\site-packages\pymysql\connections.py", line 353, in __init__
    self.connect()
  File "C:\Users\gafel\AppData\Local\Programs\Python\Python39\lib\site-packages\pymysql\connections.py", line 664, in connect
    raise exc
pymysql.err.OperationalError: (2003, "Can't connect to MySQL server on 'localhost' ([WinError 10061] Nenhuma conexão pôde ser feita porque a máquina de destino as recusou ativamente)")
2021-06-17: SQL Database reported an error: (2003, "Can't connect to MySQL server on 'localhost' ([WinError 10061] Nenhuma conexão pôde ser feita porque a máquina de destino as recusou ativamente)") 
Traceback (most recent call last):
  File "C:\Users\gafel\AppData\Local\Programs\Python\Python39\lib\site-packages\pymysql\connections.py", line 613, in connect
    sock = socket.create_connection(
  File "C:\Users\gafel\AppData\Local\Programs\Python\Python39\lib\socket.py", line 843, in create_connection
    raise err
  File "C:\Users\gafel\AppData\Local\Programs\Python\Python39\lib\socket.py", line 831, in create_connection
    sock.connect(sa)
ConnectionRefusedError: [WinError 10061] Nenhuma conexão pôde ser feita porque a máquina de destino as recusou ativamente

During handling of the above exception, another exception occurred:

Traceback (most recent call last):
  File "C:\Users\gafel\Documents\GitHub\twittery\src\database\sql\sql.py", line 12, in __init__
    self.db = pymysql.connect(host=host, port=port, user=user, passwd=password, db=db, charset='utf8')
  File "C:\Users\gafel\AppData\Local\Programs\Python\Python39\lib\site-packages\pymysql\connections.py", line 353, in __init__
    self.connect()
  File "C:\Users\gafel\AppData\Local\Programs\Python\Python39\lib\site-packages\pymysql\connections.py", line 664, in connect
    raise exc
pymysql.err.OperationalError: (2003, "Can't connect to MySQL server on 'localhost' ([WinError 10061] Nenhuma conexão pôde ser feita porque a máquina de destino as recusou ativamente)")
2021-06-17: SQL Database reported an error: (2003, "Can't connect to MySQL server on 'localhost' ([WinError 10061] Nenhuma conexão pôde ser feita porque a máquina de destino as recusou ativamente)") 
Traceback (most recent call last):
  File "C:\Users\gafel\AppData\Local\Programs\Python\Python39\lib\site-packages\pymysql\connections.py", line 613, in connect
    sock = socket.create_connection(
  File "C:\Users\gafel\AppData\Local\Programs\Python\Python39\lib\socket.py", line 843, in create_connection
    raise err
  File "C:\Users\gafel\AppData\Local\Programs\Python\Python39\lib\socket.py", line 831, in create_connection
    sock.connect(sa)
ConnectionRefusedError: [WinError 10061] Nenhuma conexão pôde ser feita porque a máquina de destino as recusou ativamente

During handling of the above exception, another exception occurred:

Traceback (most recent call last):
  File "C:\Users\gafel\Documents\GitHub\twittery\src\database\sql\sql.py", line 12, in __init__
    self.db = pymysql.connect(host=host, port=port, user=user, passwd=password, db=db, charset='utf8')
  File "C:\Users\gafel\AppData\Local\Programs\Python\Python39\lib\site-packages\pymysql\connections.py", line 353, in __init__
    self.connect()
  File "C:\Users\gafel\AppData\Local\Programs\Python\Python39\lib\site-packages\pymysql\connections.py", line 664, in connect
    raise exc
pymysql.err.OperationalError: (2003, "Can't connect to MySQL server on 'localhost' ([WinError 10061] Nenhuma conexão pôde ser feita porque a máquina de destino as recusou ativamente)")
2021-06-17: SQL Database reported an error: (2003, "Can't connect to MySQL server on 'localhost' ([WinError 10061] Nenhuma conexão pôde ser feita porque a máquina de destino as recusou ativamente)") 
Traceback (most recent call last):
  File "C:\Users\gafel\AppData\Local\Programs\Python\Python39\lib\site-packages\pymysql\connections.py", line 613, in connect
    sock = socket.create_connection(
  File "C:\Users\gafel\AppData\Local\Programs\Python\Python39\lib\socket.py", line 843, in create_connection
    raise err
  File "C:\Users\gafel\AppData\Local\Programs\Python\Python39\lib\socket.py", line 831, in create_connection
    sock.connect(sa)
ConnectionRefusedError: [WinError 10061] Nenhuma conexão pôde ser feita porque a máquina de destino as recusou ativamente

During handling of the above exception, another exception occurred:

Traceback (most recent call last):
  File "C:\Users\gafel\Documents\GitHub\twittery\src\database\sql\sql.py", line 12, in __init__
    self.db = pymysql.connect(host=host, port=port, user=user, passwd=password, db=db, charset='utf8')
  File "C:\Users\gafel\AppData\Local\Programs\Python\Python39\lib\site-packages\pymysql\connections.py", line 353, in __init__
    self.connect()
  File "C:\Users\gafel\AppData\Local\Programs\Python\Python39\lib\site-packages\pymysql\connections.py", line 664, in connect
    raise exc
pymysql.err.OperationalError: (2003, "Can't connect to MySQL server on 'localhost' ([WinError 10061] Nenhuma conexão pôde ser feita porque a máquina de destino as recusou ativamente)")
2021-06-17: SQL Database reported an error: (2003, "Can't connect to MySQL server on 'localhost' ([WinError 10061] Nenhuma conexão pôde ser feita porque a máquina de destino as recusou ativamente)") 
Traceback (most recent call last):
  File "C:\Users\gafel\AppData\Local\Programs\Python\Python39\lib\site-packages\pymysql\connections.py", line 613, in connect
    sock = socket.create_connection(
  File "C:\Users\gafel\AppData\Local\Programs\Python\Python39\lib\socket.py", line 843, in create_connection
    raise err
  File "C:\Users\gafel\AppData\Local\Programs\Python\Python39\lib\socket.py", line 831, in create_connection
    sock.connect(sa)
ConnectionRefusedError: [WinError 10061] Nenhuma conexão pôde ser feita porque a máquina de destino as recusou ativamente

During handling of the above exception, another exception occurred:

Traceback (most recent call last):
  File "C:\Users\gafel\Documents\GitHub\twittery\src\database\sql\sql.py", line 12, in __init__
    self.db = pymysql.connect(host=host, port=port, user=user, passwd=password, db=db, charset='utf8')
  File "C:\Users\gafel\AppData\Local\Programs\Python\Python39\lib\site-packages\pymysql\connections.py", line 353, in __init__
    self.connect()
  File "C:\Users\gafel\AppData\Local\Programs\Python\Python39\lib\site-packages\pymysql\connections.py", line 664, in connect
    raise exc
pymysql.err.OperationalError: (2003, "Can't connect to MySQL server on 'localhost' ([WinError 10061] Nenhuma conexão pôde ser feita porque a máquina de destino as recusou ativamente)")
2021-06-17: SQL Database reported an error: (2003, "Can't connect to MySQL server on 'localhost' ([WinError 10061] Nenhuma conexão pôde ser feita porque a máquina de destino as recusou ativamente)") 
Traceback (most recent call last):
  File "C:\Users\gafel\AppData\Local\Programs\Python\Python39\lib\site-packages\pymysql\connections.py", line 613, in connect
    sock = socket.create_connection(
  File "C:\Users\gafel\AppData\Local\Programs\Python\Python39\lib\socket.py", line 843, in create_connection
    raise err
  File "C:\Users\gafel\AppData\Local\Programs\Python\Python39\lib\socket.py", line 831, in create_connection
    sock.connect(sa)
ConnectionRefusedError: [WinError 10061] Nenhuma conexão pôde ser feita porque a máquina de destino as recusou ativamente

During handling of the above exception, another exception occurred:

Traceback (most recent call last):
  File "C:\Users\gafel\Documents\GitHub\twittery\src\database\sql\sql.py", line 12, in __init__
    self.db = pymysql.connect(host=host, port=port, user=user, passwd=password, db=db, charset='utf8')
  File "C:\Users\gafel\AppData\Local\Programs\Python\Python39\lib\site-packages\pymysql\connections.py", line 353, in __init__
    self.connect()
  File "C:\Users\gafel\AppData\Local\Programs\Python\Python39\lib\site-packages\pymysql\connections.py", line 664, in connect
    raise exc
pymysql.err.OperationalError: (2003, "Can't connect to MySQL server on 'localhost' ([WinError 10061] Nenhuma conexão pôde ser feita porque a máquina de destino as recusou ativamente)")
2021-06-17: SQL Database reported an error: (2003, "Can't connect to MySQL server on 'localhost' ([WinError 10061] Nenhuma conexão pôde ser feita porque a máquina de destino as recusou ativamente)") 
Traceback (most recent call last):
  File "C:\Users\gafel\AppData\Local\Programs\Python\Python39\lib\site-packages\pymysql\connections.py", line 613, in connect
    sock = socket.create_connection(
  File "C:\Users\gafel\AppData\Local\Programs\Python\Python39\lib\socket.py", line 843, in create_connection
    raise err
  File "C:\Users\gafel\AppData\Local\Programs\Python\Python39\lib\socket.py", line 831, in create_connection
    sock.connect(sa)
ConnectionRefusedError: [WinError 10061] Nenhuma conexão pôde ser feita porque a máquina de destino as recusou ativamente

During handling of the above exception, another exception occurred:

Traceback (most recent call last):
  File "C:\Users\gafel\Documents\GitHub\twittery\src\database\sql\sql.py", line 12, in __init__
    self.db = pymysql.connect(host=host, port=port, user=user, passwd=password, db=db, charset='utf8')
  File "C:\Users\gafel\AppData\Local\Programs\Python\Python39\lib\site-packages\pymysql\connections.py", line 353, in __init__
    self.connect()
  File "C:\Users\gafel\AppData\Local\Programs\Python\Python39\lib\site-packages\pymysql\connections.py", line 664, in connect
    raise exc
pymysql.err.OperationalError: (2003, "Can't connect to MySQL server on 'localhost' ([WinError 10061] Nenhuma conexão pôde ser feita porque a máquina de destino as recusou ativamente)")
2021-06-17: SQL Database reported an error: (2003, "Can't connect to MySQL server on 'localhost' ([WinError 10061] Nenhuma conexão pôde ser feita porque a máquina de destino as recusou ativamente)") 
Traceback (most recent call last):
  File "C:\Users\gafel\AppData\Local\Programs\Python\Python39\lib\site-packages\pymysql\connections.py", line 613, in connect
    sock = socket.create_connection(
  File "C:\Users\gafel\AppData\Local\Programs\Python\Python39\lib\socket.py", line 843, in create_connection
    raise err
  File "C:\Users\gafel\AppData\Local\Programs\Python\Python39\lib\socket.py", line 831, in create_connection
    sock.connect(sa)
ConnectionRefusedError: [WinError 10061] Nenhuma conexão pôde ser feita porque a máquina de destino as recusou ativamente

During handling of the above exception, another exception occurred:

Traceback (most recent call last):
  File "C:\Users\gafel\Documents\GitHub\twittery\src\database\sql\sql.py", line 12, in __init__
    self.db = pymysql.connect(host=host, port=port, user=user, passwd=password, db=db, charset='utf8')
  File "C:\Users\gafel\AppData\Local\Programs\Python\Python39\lib\site-packages\pymysql\connections.py", line 353, in __init__
    self.connect()
  File "C:\Users\gafel\AppData\Local\Programs\Python\Python39\lib\site-packages\pymysql\connections.py", line 664, in connect
    raise exc
pymysql.err.OperationalError: (2003, "Can't connect to MySQL server on 'localhost' ([WinError 10061] Nenhuma conexão pôde ser feita porque a máquina de destino as recusou ativamente)")
2021-06-17: SQL Database reported an error: (2003, "Can't connect to MySQL server on 'localhost' ([WinError 10061] Nenhuma conexão pôde ser feita porque a máquina de destino as recusou ativamente)") 
Traceback (most recent call last):
  File "C:\Users\gafel\AppData\Local\Programs\Python\Python39\lib\site-packages\pymysql\connections.py", line 613, in connect
    sock = socket.create_connection(
  File "C:\Users\gafel\AppData\Local\Programs\Python\Python39\lib\socket.py", line 843, in create_connection
    raise err
  File "C:\Users\gafel\AppData\Local\Programs\Python\Python39\lib\socket.py", line 831, in create_connection
    sock.connect(sa)
ConnectionRefusedError: [WinError 10061] Nenhuma conexão pôde ser feita porque a máquina de destino as recusou ativamente

During handling of the above exception, another exception occurred:

Traceback (most recent call last):
  File "C:\Users\gafel\Documents\GitHub\twittery\src\database\sql\sql.py", line 12, in __init__
    self.db = pymysql.connect(host=host, port=port, user=user, passwd=password, db=db, charset='utf8')
  File "C:\Users\gafel\AppData\Local\Programs\Python\Python39\lib\site-packages\pymysql\connections.py", line 353, in __init__
    self.connect()
  File "C:\Users\gafel\AppData\Local\Programs\Python\Python39\lib\site-packages\pymysql\connections.py", line 664, in connect
    raise exc
pymysql.err.OperationalError: (2003, "Can't connect to MySQL server on 'localhost' ([WinError 10061] Nenhuma conexão pôde ser feita porque a máquina de destino as recusou ativamente)")
2021-06-17: SQL Database reported an error: (2003, "Can't connect to MySQL server on 'localhost' ([WinError 10061] Nenhuma conexão pôde ser feita porque a máquina de destino as recusou ativamente)") 
Traceback (most recent call last):
  File "C:\Users\gafel\AppData\Local\Programs\Python\Python39\lib\site-packages\pymysql\connections.py", line 613, in connect
    sock = socket.create_connection(
  File "C:\Users\gafel\AppData\Local\Programs\Python\Python39\lib\socket.py", line 843, in create_connection
    raise err
  File "C:\Users\gafel\AppData\Local\Programs\Python\Python39\lib\socket.py", line 831, in create_connection
    sock.connect(sa)
ConnectionRefusedError: [WinError 10061] Nenhuma conexão pôde ser feita porque a máquina de destino as recusou ativamente

During handling of the above exception, another exception occurred:

Traceback (most recent call last):
  File "C:\Users\gafel\Documents\GitHub\twittery\src\database\sql\sql.py", line 12, in __init__
    self.db = pymysql.connect(host=host, port=port, user=user, passwd=password, db=db, charset='utf8')
  File "C:\Users\gafel\AppData\Local\Programs\Python\Python39\lib\site-packages\pymysql\connections.py", line 353, in __init__
    self.connect()
  File "C:\Users\gafel\AppData\Local\Programs\Python\Python39\lib\site-packages\pymysql\connections.py", line 664, in connect
    raise exc
pymysql.err.OperationalError: (2003, "Can't connect to MySQL server on 'localhost' ([WinError 10061] Nenhuma conexão pôde ser feita porque a máquina de destino as recusou ativamente)")
2021-06-17: SQL Database reported an error: (2003, "Can't connect to MySQL server on 'localhost' ([WinError 10061] Nenhuma conexão pôde ser feita porque a máquina de destino as recusou ativamente)") 
Traceback (most recent call last):
  File "C:\Users\gafel\AppData\Local\Programs\Python\Python39\lib\site-packages\pymysql\connections.py", line 613, in connect
    sock = socket.create_connection(
  File "C:\Users\gafel\AppData\Local\Programs\Python\Python39\lib\socket.py", line 843, in create_connection
    raise err
  File "C:\Users\gafel\AppData\Local\Programs\Python\Python39\lib\socket.py", line 831, in create_connection
    sock.connect(sa)
ConnectionRefusedError: [WinError 10061] Nenhuma conexão pôde ser feita porque a máquina de destino as recusou ativamente

During handling of the above exception, another exception occurred:

Traceback (most recent call last):
  File "C:\Users\gafel\Documents\GitHub\twittery\src\database\sql\sql.py", line 12, in __init__
    self.db = pymysql.connect(host=host, port=port, user=user, passwd=password, db=db, charset='utf8')
  File "C:\Users\gafel\AppData\Local\Programs\Python\Python39\lib\site-packages\pymysql\connections.py", line 353, in __init__
    self.connect()
  File "C:\Users\gafel\AppData\Local\Programs\Python\Python39\lib\site-packages\pymysql\connections.py", line 664, in connect
    raise exc
pymysql.err.OperationalError: (2003, "Can't connect to MySQL server on 'localhost' ([WinError 10061] Nenhuma conexão pôde ser feita porque a máquina de destino as recusou ativamente)")
2021-06-17: SQL Database reported an error: (2003, "Can't connect to MySQL server on 'localhost' ([WinError 10061] Nenhuma conexão pôde ser feita porque a máquina de destino as recusou ativamente)") 
Traceback (most recent call last):
  File "C:\Users\gafel\AppData\Local\Programs\Python\Python39\lib\site-packages\pymysql\connections.py", line 613, in connect
    sock = socket.create_connection(
  File "C:\Users\gafel\AppData\Local\Programs\Python\Python39\lib\socket.py", line 843, in create_connection
    raise err
  File "C:\Users\gafel\AppData\Local\Programs\Python\Python39\lib\socket.py", line 831, in create_connection
    sock.connect(sa)
ConnectionRefusedError: [WinError 10061] Nenhuma conexão pôde ser feita porque a máquina de destino as recusou ativamente

During handling of the above exception, another exception occurred:

Traceback (most recent call last):
  File "C:\Users\gafel\Documents\GitHub\twittery\src\database\sql\sql.py", line 12, in __init__
    self.db = pymysql.connect(host=host, port=port, user=user, passwd=password, db=db, charset='utf8')
  File "C:\Users\gafel\AppData\Local\Programs\Python\Python39\lib\site-packages\pymysql\connections.py", line 353, in __init__
    self.connect()
  File "C:\Users\gafel\AppData\Local\Programs\Python\Python39\lib\site-packages\pymysql\connections.py", line 664, in connect
    raise exc
pymysql.err.OperationalError: (2003, "Can't connect to MySQL server on 'localhost' ([WinError 10061] Nenhuma conexão pôde ser feita porque a máquina de destino as recusou ativamente)")
2021-06-17: SQL Database reported an error: (2003, "Can't connect to MySQL server on 'localhost' ([WinError 10061] Nenhuma conexão pôde ser feita porque a máquina de destino as recusou ativamente)") 
Traceback (most recent call last):
  File "C:\Users\gafel\AppData\Local\Programs\Python\Python39\lib\site-packages\pymysql\connections.py", line 613, in connect
    sock = socket.create_connection(
  File "C:\Users\gafel\AppData\Local\Programs\Python\Python39\lib\socket.py", line 843, in create_connection
    raise err
  File "C:\Users\gafel\AppData\Local\Programs\Python\Python39\lib\socket.py", line 831, in create_connection
    sock.connect(sa)
ConnectionRefusedError: [WinError 10061] Nenhuma conexão pôde ser feita porque a máquina de destino as recusou ativamente

During handling of the above exception, another exception occurred:

Traceback (most recent call last):
  File "C:\Users\gafel\Documents\GitHub\twittery\src\database\sql\sql.py", line 12, in __init__
    self.db = pymysql.connect(host=host, port=port, user=user, passwd=password, db=db, charset='utf8')
  File "C:\Users\gafel\AppData\Local\Programs\Python\Python39\lib\site-packages\pymysql\connections.py", line 353, in __init__
    self.connect()
  File "C:\Users\gafel\AppData\Local\Programs\Python\Python39\lib\site-packages\pymysql\connections.py", line 664, in connect
    raise exc
pymysql.err.OperationalError: (2003, "Can't connect to MySQL server on 'localhost' ([WinError 10061] Nenhuma conexão pôde ser feita porque a máquina de destino as recusou ativamente)")
2021-06-17: SQL Database reported an error: (2003, "Can't connect to MySQL server on 'localhost' ([WinError 10061] Nenhuma conexão pôde ser feita porque a máquina de destino as recusou ativamente)") 
Traceback (most recent call last):
  File "C:\Users\gafel\AppData\Local\Programs\Python\Python39\lib\site-packages\pymysql\connections.py", line 613, in connect
    sock = socket.create_connection(
  File "C:\Users\gafel\AppData\Local\Programs\Python\Python39\lib\socket.py", line 843, in create_connection
    raise err
  File "C:\Users\gafel\AppData\Local\Programs\Python\Python39\lib\socket.py", line 831, in create_connection
    sock.connect(sa)
ConnectionRefusedError: [WinError 10061] Nenhuma conexão pôde ser feita porque a máquina de destino as recusou ativamente

During handling of the above exception, another exception occurred:

Traceback (most recent call last):
  File "C:\Users\gafel\Documents\GitHub\twittery\src\database\sql\sql.py", line 12, in __init__
    self.db = pymysql.connect(host=host, port=port, user=user, passwd=password, db=db, charset='utf8')
  File "C:\Users\gafel\AppData\Local\Programs\Python\Python39\lib\site-packages\pymysql\connections.py", line 353, in __init__
    self.connect()
  File "C:\Users\gafel\AppData\Local\Programs\Python\Python39\lib\site-packages\pymysql\connections.py", line 664, in connect
    raise exc
pymysql.err.OperationalError: (2003, "Can't connect to MySQL server on 'localhost' ([WinError 10061] Nenhuma conexão pôde ser feita porque a máquina de destino as recusou ativamente)")
2021-06-17: SQL Database reported an error: (2003, "Can't connect to MySQL server on 'localhost' ([WinError 10061] Nenhuma conexão pôde ser feita porque a máquina de destino as recusou ativamente)") 
Traceback (most recent call last):
  File "C:\Users\gafel\AppData\Local\Programs\Python\Python39\lib\site-packages\pymysql\connections.py", line 613, in connect
    sock = socket.create_connection(
  File "C:\Users\gafel\AppData\Local\Programs\Python\Python39\lib\socket.py", line 843, in create_connection
    raise err
  File "C:\Users\gafel\AppData\Local\Programs\Python\Python39\lib\socket.py", line 831, in create_connection
    sock.connect(sa)
ConnectionRefusedError: [WinError 10061] Nenhuma conexão pôde ser feita porque a máquina de destino as recusou ativamente

During handling of the above exception, another exception occurred:

Traceback (most recent call last):
  File "C:\Users\gafel\Documents\GitHub\twittery\src\database\sql\sql.py", line 12, in __init__
    self.db = pymysql.connect(host=host, port=port, user=user, passwd=password, db=db, charset='utf8')
  File "C:\Users\gafel\AppData\Local\Programs\Python\Python39\lib\site-packages\pymysql\connections.py", line 353, in __init__
    self.connect()
  File "C:\Users\gafel\AppData\Local\Programs\Python\Python39\lib\site-packages\pymysql\connections.py", line 664, in connect
    raise exc
pymysql.err.OperationalError: (2003, "Can't connect to MySQL server on 'localhost' ([WinError 10061] Nenhuma conexão pôde ser feita porque a máquina de destino as recusou ativamente)")
2021-06-17: SQL Database reported an error: (2003, "Can't connect to MySQL server on 'localhost' ([WinError 10061] Nenhuma conexão pôde ser feita porque a máquina de destino as recusou ativamente)") 
Traceback (most recent call last):
  File "C:\Users\gafel\AppData\Local\Programs\Python\Python39\lib\site-packages\pymysql\connections.py", line 613, in connect
    sock = socket.create_connection(
  File "C:\Users\gafel\AppData\Local\Programs\Python\Python39\lib\socket.py", line 843, in create_connection
    raise err
  File "C:\Users\gafel\AppData\Local\Programs\Python\Python39\lib\socket.py", line 831, in create_connection
    sock.connect(sa)
ConnectionRefusedError: [WinError 10061] Nenhuma conexão pôde ser feita porque a máquina de destino as recusou ativamente

During handling of the above exception, another exception occurred:

Traceback (most recent call last):
  File "C:\Users\gafel\Documents\GitHub\twittery\src\database\sql\sql.py", line 12, in __init__
    self.db = pymysql.connect(host=host, port=port, user=user, passwd=password, db=db, charset='utf8')
  File "C:\Users\gafel\AppData\Local\Programs\Python\Python39\lib\site-packages\pymysql\connections.py", line 353, in __init__
    self.connect()
  File "C:\Users\gafel\AppData\Local\Programs\Python\Python39\lib\site-packages\pymysql\connections.py", line 664, in connect
    raise exc
pymysql.err.OperationalError: (2003, "Can't connect to MySQL server on 'localhost' ([WinError 10061] Nenhuma conexão pôde ser feita porque a máquina de destino as recusou ativamente)")
2021-06-17: SQL Database reported an error: (2003, "Can't connect to MySQL server on 'localhost' ([WinError 10061] Nenhuma conexão pôde ser feita porque a máquina de destino as recusou ativamente)") 
Traceback (most recent call last):
  File "C:\Users\gafel\AppData\Local\Programs\Python\Python39\lib\site-packages\pymysql\connections.py", line 613, in connect
    sock = socket.create_connection(
  File "C:\Users\gafel\AppData\Local\Programs\Python\Python39\lib\socket.py", line 843, in create_connection
    raise err
  File "C:\Users\gafel\AppData\Local\Programs\Python\Python39\lib\socket.py", line 831, in create_connection
    sock.connect(sa)
ConnectionRefusedError: [WinError 10061] Nenhuma conexão pôde ser feita porque a máquina de destino as recusou ativamente

During handling of the above exception, another exception occurred:

Traceback (most recent call last):
  File "C:\Users\gafel\Documents\GitHub\twittery\src\database\sql\sql.py", line 12, in __init__
    self.db = pymysql.connect(host=host, port=port, user=user, passwd=password, db=db, charset='utf8')
  File "C:\Users\gafel\AppData\Local\Programs\Python\Python39\lib\site-packages\pymysql\connections.py", line 353, in __init__
    self.connect()
  File "C:\Users\gafel\AppData\Local\Programs\Python\Python39\lib\site-packages\pymysql\connections.py", line 664, in connect
    raise exc
pymysql.err.OperationalError: (2003, "Can't connect to MySQL server on 'localhost' ([WinError 10061] Nenhuma conexão pôde ser feita porque a máquina de destino as recusou ativamente)")
2021-06-17: SQL Database reported an error: (2003, "Can't connect to MySQL server on 'localhost' ([WinError 10061] Nenhuma conexão pôde ser feita porque a máquina de destino as recusou ativamente)") 
Traceback (most recent call last):
  File "C:\Users\gafel\AppData\Local\Programs\Python\Python39\lib\site-packages\pymysql\connections.py", line 613, in connect
    sock = socket.create_connection(
  File "C:\Users\gafel\AppData\Local\Programs\Python\Python39\lib\socket.py", line 843, in create_connection
    raise err
  File "C:\Users\gafel\AppData\Local\Programs\Python\Python39\lib\socket.py", line 831, in create_connection
    sock.connect(sa)
ConnectionRefusedError: [WinError 10061] Nenhuma conexão pôde ser feita porque a máquina de destino as recusou ativamente

During handling of the above exception, another exception occurred:

Traceback (most recent call last):
  File "C:\Users\gafel\Documents\GitHub\twittery\src\database\sql\sql.py", line 12, in __init__
    self.db = pymysql.connect(host=host, port=port, user=user, passwd=password, db=db, charset='utf8')
  File "C:\Users\gafel\AppData\Local\Programs\Python\Python39\lib\site-packages\pymysql\connections.py", line 353, in __init__
    self.connect()
  File "C:\Users\gafel\AppData\Local\Programs\Python\Python39\lib\site-packages\pymysql\connections.py", line 664, in connect
    raise exc
pymysql.err.OperationalError: (2003, "Can't connect to MySQL server on 'localhost' ([WinError 10061] Nenhuma conexão pôde ser feita porque a máquina de destino as recusou ativamente)")
2021-06-17: SQL Database reported an error: (2003, "Can't connect to MySQL server on 'localhost' ([WinError 10061] Nenhuma conexão pôde ser feita porque a máquina de destino as recusou ativamente)") 
Traceback (most recent call last):
  File "C:\Users\gafel\AppData\Local\Programs\Python\Python39\lib\site-packages\pymysql\connections.py", line 613, in connect
    sock = socket.create_connection(
  File "C:\Users\gafel\AppData\Local\Programs\Python\Python39\lib\socket.py", line 843, in create_connection
    raise err
  File "C:\Users\gafel\AppData\Local\Programs\Python\Python39\lib\socket.py", line 831, in create_connection
    sock.connect(sa)
ConnectionRefusedError: [WinError 10061] Nenhuma conexão pôde ser feita porque a máquina de destino as recusou ativamente

During handling of the above exception, another exception occurred:

Traceback (most recent call last):
  File "C:\Users\gafel\Documents\GitHub\twittery\src\database\sql\sql.py", line 12, in __init__
    self.db = pymysql.connect(host=host, port=port, user=user, passwd=password, db=db, charset='utf8')
  File "C:\Users\gafel\AppData\Local\Programs\Python\Python39\lib\site-packages\pymysql\connections.py", line 353, in __init__
    self.connect()
  File "C:\Users\gafel\AppData\Local\Programs\Python\Python39\lib\site-packages\pymysql\connections.py", line 664, in connect
    raise exc
pymysql.err.OperationalError: (2003, "Can't connect to MySQL server on 'localhost' ([WinError 10061] Nenhuma conexão pôde ser feita porque a máquina de destino as recusou ativamente)")
2021-06-17: SQL Database reported an error: (2003, "Can't connect to MySQL server on 'localhost' ([WinError 10061] Nenhuma conexão pôde ser feita porque a máquina de destino as recusou ativamente)") 
Traceback (most recent call last):
  File "C:\Users\gafel\AppData\Local\Programs\Python\Python39\lib\site-packages\pymysql\connections.py", line 613, in connect
    sock = socket.create_connection(
  File "C:\Users\gafel\AppData\Local\Programs\Python\Python39\lib\socket.py", line 843, in create_connection
    raise err
  File "C:\Users\gafel\AppData\Local\Programs\Python\Python39\lib\socket.py", line 831, in create_connection
    sock.connect(sa)
ConnectionRefusedError: [WinError 10061] Nenhuma conexão pôde ser feita porque a máquina de destino as recusou ativamente

During handling of the above exception, another exception occurred:

Traceback (most recent call last):
  File "C:\Users\gafel\Documents\GitHub\twittery\src\database\sql\sql.py", line 12, in __init__
    self.db = pymysql.connect(host=host, port=port, user=user, passwd=password, db=db, charset='utf8')
  File "C:\Users\gafel\AppData\Local\Programs\Python\Python39\lib\site-packages\pymysql\connections.py", line 353, in __init__
    self.connect()
  File "C:\Users\gafel\AppData\Local\Programs\Python\Python39\lib\site-packages\pymysql\connections.py", line 664, in connect
    raise exc
pymysql.err.OperationalError: (2003, "Can't connect to MySQL server on 'localhost' ([WinError 10061] Nenhuma conexão pôde ser feita porque a máquina de destino as recusou ativamente)")
2021-06-17: SQL Database reported an error: (2003, "Can't connect to MySQL server on 'localhost' ([WinError 10061] Nenhuma conexão pôde ser feita porque a máquina de destino as recusou ativamente)") 
Traceback (most recent call last):
  File "C:\Users\gafel\AppData\Local\Programs\Python\Python39\lib\site-packages\pymysql\connections.py", line 613, in connect
    sock = socket.create_connection(
  File "C:\Users\gafel\AppData\Local\Programs\Python\Python39\lib\socket.py", line 843, in create_connection
    raise err
  File "C:\Users\gafel\AppData\Local\Programs\Python\Python39\lib\socket.py", line 831, in create_connection
    sock.connect(sa)
ConnectionRefusedError: [WinError 10061] Nenhuma conexão pôde ser feita porque a máquina de destino as recusou ativamente

During handling of the above exception, another exception occurred:

Traceback (most recent call last):
  File "C:\Users\gafel\Documents\GitHub\twittery\src\database\sql\sql.py", line 12, in __init__
    self.db = pymysql.connect(host=host, port=port, user=user, passwd=password, db=db, charset='utf8')
  File "C:\Users\gafel\AppData\Local\Programs\Python\Python39\lib\site-packages\pymysql\connections.py", line 353, in __init__
    self.connect()
  File "C:\Users\gafel\AppData\Local\Programs\Python\Python39\lib\site-packages\pymysql\connections.py", line 664, in connect
    raise exc
pymysql.err.OperationalError: (2003, "Can't connect to MySQL server on 'localhost' ([WinError 10061] Nenhuma conexão pôde ser feita porque a máquina de destino as recusou ativamente)")
2021-06-17: SQL Database reported an error: (2003, "Can't connect to MySQL server on 'localhost' ([WinError 10061] Nenhuma conexão pôde ser feita porque a máquina de destino as recusou ativamente)") 
Traceback (most recent call last):
  File "C:\Users\gafel\AppData\Local\Programs\Python\Python39\lib\site-packages\pymysql\connections.py", line 613, in connect
    sock = socket.create_connection(
  File "C:\Users\gafel\AppData\Local\Programs\Python\Python39\lib\socket.py", line 843, in create_connection
    raise err
  File "C:\Users\gafel\AppData\Local\Programs\Python\Python39\lib\socket.py", line 831, in create_connection
    sock.connect(sa)
ConnectionRefusedError: [WinError 10061] Nenhuma conexão pôde ser feita porque a máquina de destino as recusou ativamente

During handling of the above exception, another exception occurred:

Traceback (most recent call last):
  File "C:\Users\gafel\Documents\GitHub\twittery\src\database\sql\sql.py", line 12, in __init__
    self.db = pymysql.connect(host=host, port=port, user=user, passwd=password, db=db, charset='utf8')
  File "C:\Users\gafel\AppData\Local\Programs\Python\Python39\lib\site-packages\pymysql\connections.py", line 353, in __init__
    self.connect()
  File "C:\Users\gafel\AppData\Local\Programs\Python\Python39\lib\site-packages\pymysql\connections.py", line 664, in connect
    raise exc
pymysql.err.OperationalError: (2003, "Can't connect to MySQL server on 'localhost' ([WinError 10061] Nenhuma conexão pôde ser feita porque a máquina de destino as recusou ativamente)")
2021-06-17: SQL Database reported an error: (2003, "Can't connect to MySQL server on 'localhost' ([WinError 10061] Nenhuma conexão pôde ser feita porque a máquina de destino as recusou ativamente)") 
Traceback (most recent call last):
  File "C:\Users\gafel\AppData\Local\Programs\Python\Python39\lib\site-packages\pymysql\connections.py", line 613, in connect
    sock = socket.create_connection(
  File "C:\Users\gafel\AppData\Local\Programs\Python\Python39\lib\socket.py", line 843, in create_connection
    raise err
  File "C:\Users\gafel\AppData\Local\Programs\Python\Python39\lib\socket.py", line 831, in create_connection
    sock.connect(sa)
ConnectionRefusedError: [WinError 10061] Nenhuma conexão pôde ser feita porque a máquina de destino as recusou ativamente

During handling of the above exception, another exception occurred:

Traceback (most recent call last):
  File "C:\Users\gafel\Documents\GitHub\twittery\src\database\sql\sql.py", line 12, in __init__
    self.db = pymysql.connect(host=host, port=port, user=user, passwd=password, db=db, charset='utf8')
  File "C:\Users\gafel\AppData\Local\Programs\Python\Python39\lib\site-packages\pymysql\connections.py", line 353, in __init__
    self.connect()
  File "C:\Users\gafel\AppData\Local\Programs\Python\Python39\lib\site-packages\pymysql\connections.py", line 664, in connect
    raise exc
pymysql.err.OperationalError: (2003, "Can't connect to MySQL server on 'localhost' ([WinError 10061] Nenhuma conexão pôde ser feita porque a máquina de destino as recusou ativamente)")
2021-06-17: SQL Database reported an error: (2003, "Can't connect to MySQL server on 'localhost' ([WinError 10061] Nenhuma conexão pôde ser feita porque a máquina de destino as recusou ativamente)") 
Traceback (most recent call last):
  File "C:\Users\gafel\AppData\Local\Programs\Python\Python39\lib\site-packages\pymysql\connections.py", line 613, in connect
    sock = socket.create_connection(
  File "C:\Users\gafel\AppData\Local\Programs\Python\Python39\lib\socket.py", line 843, in create_connection
    raise err
  File "C:\Users\gafel\AppData\Local\Programs\Python\Python39\lib\socket.py", line 831, in create_connection
    sock.connect(sa)
ConnectionRefusedError: [WinError 10061] Nenhuma conexão pôde ser feita porque a máquina de destino as recusou ativamente

During handling of the above exception, another exception occurred:

Traceback (most recent call last):
  File "C:\Users\gafel\Documents\GitHub\twittery\src\database\sql\sql.py", line 12, in __init__
    self.db = pymysql.connect(host=host, port=port, user=user, passwd=password, db=db, charset='utf8')
  File "C:\Users\gafel\AppData\Local\Programs\Python\Python39\lib\site-packages\pymysql\connections.py", line 353, in __init__
    self.connect()
  File "C:\Users\gafel\AppData\Local\Programs\Python\Python39\lib\site-packages\pymysql\connections.py", line 664, in connect
    raise exc
pymysql.err.OperationalError: (2003, "Can't connect to MySQL server on 'localhost' ([WinError 10061] Nenhuma conexão pôde ser feita porque a máquina de destino as recusou ativamente)")
2021-06-17: SQL Database reported an error: (2003, "Can't connect to MySQL server on 'localhost' ([WinError 10061] Nenhuma conexão pôde ser feita porque a máquina de destino as recusou ativamente)") 
Traceback (most recent call last):
  File "C:\Users\gafel\AppData\Local\Programs\Python\Python39\lib\site-packages\pymysql\connections.py", line 613, in connect
    sock = socket.create_connection(
  File "C:\Users\gafel\AppData\Local\Programs\Python\Python39\lib\socket.py", line 843, in create_connection
    raise err
  File "C:\Users\gafel\AppData\Local\Programs\Python\Python39\lib\socket.py", line 831, in create_connection
    sock.connect(sa)
ConnectionRefusedError: [WinError 10061] Nenhuma conexão pôde ser feita porque a máquina de destino as recusou ativamente

During handling of the above exception, another exception occurred:

Traceback (most recent call last):
  File "C:\Users\gafel\Documents\GitHub\twittery\src\database\sql\sql.py", line 12, in __init__
    self.db = pymysql.connect(host=host, port=port, user=user, passwd=password, db=db, charset='utf8')
  File "C:\Users\gafel\AppData\Local\Programs\Python\Python39\lib\site-packages\pymysql\connections.py", line 353, in __init__
    self.connect()
  File "C:\Users\gafel\AppData\Local\Programs\Python\Python39\lib\site-packages\pymysql\connections.py", line 664, in connect
    raise exc
pymysql.err.OperationalError: (2003, "Can't connect to MySQL server on 'localhost' ([WinError 10061] Nenhuma conexão pôde ser feita porque a máquina de destino as recusou ativamente)")
2021-06-17: SQL Database reported an error: (2003, "Can't connect to MySQL server on 'localhost' ([WinError 10061] Nenhuma conexão pôde ser feita porque a máquina de destino as recusou ativamente)") 
Traceback (most recent call last):
  File "C:\Users\gafel\AppData\Local\Programs\Python\Python39\lib\site-packages\pymysql\connections.py", line 613, in connect
    sock = socket.create_connection(
  File "C:\Users\gafel\AppData\Local\Programs\Python\Python39\lib\socket.py", line 843, in create_connection
    raise err
  File "C:\Users\gafel\AppData\Local\Programs\Python\Python39\lib\socket.py", line 831, in create_connection
    sock.connect(sa)
ConnectionRefusedError: [WinError 10061] Nenhuma conexão pôde ser feita porque a máquina de destino as recusou ativamente

During handling of the above exception, another exception occurred:

Traceback (most recent call last):
  File "C:\Users\gafel\Documents\GitHub\twittery\src\database\sql\sql.py", line 12, in __init__
    self.db = pymysql.connect(host=host, port=port, user=user, passwd=password, db=db, charset='utf8')
  File "C:\Users\gafel\AppData\Local\Programs\Python\Python39\lib\site-packages\pymysql\connections.py", line 353, in __init__
    self.connect()
  File "C:\Users\gafel\AppData\Local\Programs\Python\Python39\lib\site-packages\pymysql\connections.py", line 664, in connect
    raise exc
pymysql.err.OperationalError: (2003, "Can't connect to MySQL server on 'localhost' ([WinError 10061] Nenhuma conexão pôde ser feita porque a máquina de destino as recusou ativamente)")
2021-06-17: SQL Database reported an error: (2003, "Can't connect to MySQL server on 'localhost' ([WinError 10061] Nenhuma conexão pôde ser feita porque a máquina de destino as recusou ativamente)") 
Traceback (most recent call last):
  File "C:\Users\gafel\AppData\Local\Programs\Python\Python39\lib\site-packages\pymysql\connections.py", line 613, in connect
    sock = socket.create_connection(
  File "C:\Users\gafel\AppData\Local\Programs\Python\Python39\lib\socket.py", line 843, in create_connection
    raise err
  File "C:\Users\gafel\AppData\Local\Programs\Python\Python39\lib\socket.py", line 831, in create_connection
    sock.connect(sa)
ConnectionRefusedError: [WinError 10061] Nenhuma conexão pôde ser feita porque a máquina de destino as recusou ativamente

During handling of the above exception, another exception occurred:

Traceback (most recent call last):
  File "C:\Users\gafel\Documents\GitHub\twittery\src\database\sql\sql.py", line 12, in __init__
    self.db = pymysql.connect(host=host, port=port, user=user, passwd=password, db=db, charset='utf8')
  File "C:\Users\gafel\AppData\Local\Programs\Python\Python39\lib\site-packages\pymysql\connections.py", line 353, in __init__
    self.connect()
  File "C:\Users\gafel\AppData\Local\Programs\Python\Python39\lib\site-packages\pymysql\connections.py", line 664, in connect
    raise exc
pymysql.err.OperationalError: (2003, "Can't connect to MySQL server on 'localhost' ([WinError 10061] Nenhuma conexão pôde ser feita porque a máquina de destino as recusou ativamente)")
2021-06-17: SQL Database reported an error: (2003, "Can't connect to MySQL server on 'localhost' ([WinError 10061] Nenhuma conexão pôde ser feita porque a máquina de destino as recusou ativamente)") 
Traceback (most recent call last):
  File "C:\Users\gafel\AppData\Local\Programs\Python\Python39\lib\site-packages\pymysql\connections.py", line 613, in connect
    sock = socket.create_connection(
  File "C:\Users\gafel\AppData\Local\Programs\Python\Python39\lib\socket.py", line 843, in create_connection
    raise err
  File "C:\Users\gafel\AppData\Local\Programs\Python\Python39\lib\socket.py", line 831, in create_connection
    sock.connect(sa)
ConnectionRefusedError: [WinError 10061] Nenhuma conexão pôde ser feita porque a máquina de destino as recusou ativamente

During handling of the above exception, another exception occurred:

Traceback (most recent call last):
  File "C:\Users\gafel\Documents\GitHub\twittery\src\database\sql\sql.py", line 12, in __init__
    self.db = pymysql.connect(host=host, port=port, user=user, passwd=password, db=db, charset='utf8')
  File "C:\Users\gafel\AppData\Local\Programs\Python\Python39\lib\site-packages\pymysql\connections.py", line 353, in __init__
    self.connect()
  File "C:\Users\gafel\AppData\Local\Programs\Python\Python39\lib\site-packages\pymysql\connections.py", line 664, in connect
    raise exc
pymysql.err.OperationalError: (2003, "Can't connect to MySQL server on 'localhost' ([WinError 10061] Nenhuma conexão pôde ser feita porque a máquina de destino as recusou ativamente)")
2021-06-17: SQL Database reported an error: (2003, "Can't connect to MySQL server on 'localhost' ([WinError 10061] Nenhuma conexão pôde ser feita porque a máquina de destino as recusou ativamente)") 
Traceback (most recent call last):
  File "C:\Users\gafel\AppData\Local\Programs\Python\Python39\lib\site-packages\pymysql\connections.py", line 613, in connect
    sock = socket.create_connection(
  File "C:\Users\gafel\AppData\Local\Programs\Python\Python39\lib\socket.py", line 843, in create_connection
    raise err
  File "C:\Users\gafel\AppData\Local\Programs\Python\Python39\lib\socket.py", line 831, in create_connection
    sock.connect(sa)
ConnectionRefusedError: [WinError 10061] Nenhuma conexão pôde ser feita porque a máquina de destino as recusou ativamente

During handling of the above exception, another exception occurred:

Traceback (most recent call last):
  File "C:\Users\gafel\Documents\GitHub\twittery\src\database\sql\sql.py", line 12, in __init__
    self.db = pymysql.connect(host=host, port=port, user=user, passwd=password, db=db, charset='utf8')
  File "C:\Users\gafel\AppData\Local\Programs\Python\Python39\lib\site-packages\pymysql\connections.py", line 353, in __init__
    self.connect()
  File "C:\Users\gafel\AppData\Local\Programs\Python\Python39\lib\site-packages\pymysql\connections.py", line 664, in connect
    raise exc
pymysql.err.OperationalError: (2003, "Can't connect to MySQL server on 'localhost' ([WinError 10061] Nenhuma conexão pôde ser feita porque a máquina de destino as recusou ativamente)")
2021-06-17: SQL Database reported an error: (2003, "Can't connect to MySQL server on 'localhost' ([WinError 10061] Nenhuma conexão pôde ser feita porque a máquina de destino as recusou ativamente)") 
Traceback (most recent call last):
  File "C:\Users\gafel\AppData\Local\Programs\Python\Python39\lib\site-packages\pymysql\connections.py", line 613, in connect
    sock = socket.create_connection(
  File "C:\Users\gafel\AppData\Local\Programs\Python\Python39\lib\socket.py", line 843, in create_connection
    raise err
  File "C:\Users\gafel\AppData\Local\Programs\Python\Python39\lib\socket.py", line 831, in create_connection
    sock.connect(sa)
ConnectionRefusedError: [WinError 10061] Nenhuma conexão pôde ser feita porque a máquina de destino as recusou ativamente

During handling of the above exception, another exception occurred:

Traceback (most recent call last):
  File "C:\Users\gafel\Documents\GitHub\twittery\src\database\sql\sql.py", line 12, in __init__
    self.db = pymysql.connect(host=host, port=port, user=user, passwd=password, db=db, charset='utf8')
  File "C:\Users\gafel\AppData\Local\Programs\Python\Python39\lib\site-packages\pymysql\connections.py", line 353, in __init__
    self.connect()
  File "C:\Users\gafel\AppData\Local\Programs\Python\Python39\lib\site-packages\pymysql\connections.py", line 664, in connect
    raise exc
pymysql.err.OperationalError: (2003, "Can't connect to MySQL server on 'localhost' ([WinError 10061] Nenhuma conexão pôde ser feita porque a máquina de destino as recusou ativamente)")
2021-06-17: SQL Database reported an error: (2003, "Can't connect to MySQL server on 'localhost' ([WinError 10061] Nenhuma conexão pôde ser feita porque a máquina de destino as recusou ativamente)") 
Traceback (most recent call last):
  File "C:\Users\gafel\AppData\Local\Programs\Python\Python39\lib\site-packages\pymysql\connections.py", line 613, in connect
    sock = socket.create_connection(
  File "C:\Users\gafel\AppData\Local\Programs\Python\Python39\lib\socket.py", line 843, in create_connection
    raise err
  File "C:\Users\gafel\AppData\Local\Programs\Python\Python39\lib\socket.py", line 831, in create_connection
    sock.connect(sa)
ConnectionRefusedError: [WinError 10061] Nenhuma conexão pôde ser feita porque a máquina de destino as recusou ativamente

During handling of the above exception, another exception occurred:

Traceback (most recent call last):
  File "C:\Users\gafel\Documents\GitHub\twittery\src\database\sql\sql.py", line 12, in __init__
    self.db = pymysql.connect(host=host, port=port, user=user, passwd=password, db=db, charset='utf8')
  File "C:\Users\gafel\AppData\Local\Programs\Python\Python39\lib\site-packages\pymysql\connections.py", line 353, in __init__
    self.connect()
  File "C:\Users\gafel\AppData\Local\Programs\Python\Python39\lib\site-packages\pymysql\connections.py", line 664, in connect
    raise exc
pymysql.err.OperationalError: (2003, "Can't connect to MySQL server on 'localhost' ([WinError 10061] Nenhuma conexão pôde ser feita porque a máquina de destino as recusou ativamente)")
